Workbook

Sheet Ppto 24-25 2Oct
C2: 2023/2024 | P2: 2024/2025
C3: Sep | D3: Oct | E3: Nov | F3: Dic | G3: Ene | H3: Feb | I3: Mar | J3: Abr | K3: May | L3: Jun | M3: Jul | N3: Ago | O3: Totales | P3: Sep | Q3: Oct | R3: Nov | S3: Dic | T3: Ene | U3: Feb | V3: Mar | W3: Abr | X3: May | Y3: Jun | Z3: Jul | AA3: Ago | AB3: Totales
B4: Vacuno
B5: Cobros | C5: 556.3 | D5: 33077.51 | E5: 51305.32 | F5: 0 | G5: 37253.67 | H5: 0 | I5: 0 | J5: 24907.2 | K5: 32803.2 | L5: 19326.06 | M5: 2174.17 | N5: 17183.67 | O5: 218587.1 | P5: 20013.44 | Q5: 9188.82 | R5: 12093 | S5: 14132.5 | T5: 13450 | U5: 8561.19 | V5: 13856.19 | W5: 8349 | X5: 22011 | Y5: 29601 | Z5: 15180 | AA5: 14049 | AB5: 180485.14
B6: Pagos | C6: 0 | D6: 0 | E6: 2310.58 | F6: 836.06 | G6: 4329.7136 | H6: 16.5 | I6: 383.08 | J6: 2104.36 | K6: 637.4 | L6: 632.11 | M6: 3107.17 | N6: 791.98 | O6: 15148.954 | P6: 705.64 | Q6: 2948.81 | R6: -1142.77 | S6: 700 | T6: 5568.9036 | U6: 600 | V6: 1300 | W6: 1574.56 | X6: 725 | Y6: 600 | Z6: 2961.41 | AA6: 600 | AB6: 17141.554
B8: Caja Operaciones (mes) | C8: 556.3 | D8: 33077.51 | E8: 48994.74 | F8: -836.06 | G8: 32923.956 | H8: -16.5 | I8: -383.08 | J8: 22802.84 | K8: 32165.8 | L8: 18693.95 | M8: -933 | N8: 16391.69 | P8: 19307.8 | Q8: 6240.01 | R8: 13235.77 | S8: 13432.5 | T8: 7881.0964 | U8: 7961.19 | V8: 12556.19 | W8: 6774.44 | X8: 21286 | Y8: 29001 | Z8: 12218.59 | AA8: 13449
B9: Caja Operaciones (acum.) | C9: 556.3 | D9: 33633.81 | E9: 82628.55 | F9: 81792.49 | G9: 114716.45 | H9: 114699.95 | I9: 114316.87 | J9: 137119.71 | K9: 169285.51 | L9: 187979.46 | M9: 187046.46 | N9: 203438.15 | O9: 203438.15 | P9: 19307.8 | Q9: 25547.81 | R9: 38783.58 | S9: 52216.08 | T9: 60097.176 | U9: 68058.366 | V9: 80614.556 | W9: 87388.996 | X9: 108675 | Y9: 137676 | Z9: 149894.59 | AA9: 163343.59 | AB9: 163343.59
B10: Porcino
B11: Cobros | C11: 4256.95 | D11: 280.97 | E11: 7918.95 | F11: 5851.53 | G11: 6817.68 | H11: 1725.36 | I11: 2334.57 | J11: 34055.67 | K11: 47976.1 | L11: 21953.81 | M11: 11.84 | N11: 7039.33 | O11: 140222.76 | P11: 1689.99 | Q11: 7042.67 | R11: 0 | S11: 0 | T11: 33800 | U11: 4032 | V11: 0 | W11: 0 | X11: 0 | Y11: 30000 | Z11: 60480 | AA11: 0 | AB11: 137044.66
B12: Pagos | C12: 0 | D12: 2580.26 | E12: 4060.27 | F12: 5231.09 | G12: 6014.37 | H12: 3635.26 | I12: 1494.8879 | J12: 6161.82 | K12: 6469.54 | L12: 6495.07 | M12: 5823.66 | N12: 2236.42 | O12: 50202.648 | P12: 1967.14 | Q12: 10 | R12: 186.08 | S12: 1251.77 | T12: 1416.14 | U12: 749.76 | V12: 260 | W12: 260 | X12: 260 | Y12: 260 | Z12: 260 | AA12: 260 | AB12: 7140.89
B14: Caja Operaciones (mes) | C14: 4256.95 | D14: -2299.29 | E14: 3858.68 | F14: 620.44 | G14: 803.31 | H14: -1909.9 | I14: 839.6821 | J14: 27893.85 | K14: 41506.56 | L14: 15458.74 | M14: -5811.82 | N14: 4802.91 | P14: -277.15 | Q14: 7032.67 | R14: -186.08 | S14: -1251.77 | T14: 32383.86 | U14: 3282.24 | V14: -260 | W14: -260 | X14: -260 | Y14: 29740 | Z14: 60220 | AA14: -260
B15: Caja Operaciones (acum.) | C15: 4256.95 | D15: 1957.66 | E15: 5816.34 | F15: 6436.78 | G15: 7240.09 | H15: 5330.19 | I15: 6169.8721 | J15: 34063.722 | K15: 75570.282 | L15: 91029.022 | M15: 85217.202 | N15: 90020.112 | O15: 90020.112 | P15: -277.15 | Q15: 6755.52 | R15: 6569.44 | S15: 5317.67 | T15: 37701.53 | U15: 40983.77 | V15: 40723.77 | W15: 40463.77 | X15: 40203.77 | Y15: 69943.77 | Z15: 130163.77 | AA15: 129903.77 | AB15: 129903.77
B16: Ovino
B17: Cobros | C17: 0 | D17: 0 | E17: 11902 | F17: 0 | G17: 2858.9 | H17: 0 | I17: 0 | J17: 0 | K17: 0 | L17: 0 | M17: 0 | N17: 0 | O17: 14760.9 | P17: 0 | Q17: 0 | R17: 0 | S17: 0 | T17: 0 | U17: 0 | V17: 0 | W17: 0 | X17: 0 | Y17: 0 | Z17: 0 | AA17: 0 | AB17: 0
B18: Pagos | C18: 0 | D18: 0 | E18: 363.84 | F18: 50.2 | G18: 0 | H18: 0 | I18: 0 | J18: 0 | K18: 16.5 | L18: 0 | M18: 0 | N18: 0 | O18: 430.54 | P18: 0 | Q18: 0 | R18: 0 | S18: 0 | T18: 0 | U18: 0 | V18: 0 | W18: 0 | X18: 0 | Y18: 0 | Z18: 0 | AA18: 0 | AB18: 0
B20: Caja Operaciones (mes) | C20: 0 | D20: 0 | E20: 11538.16 | F20: -50.2 | G20: 2858.9 | H20: 0 | I20: 0 | J20: 0 | K20: -16.5 | L20: 0 | M20: 0 | N20: 0 | P20: 0 | Q20: 0 | R20: 0 | S20: 0 | T20: 0 | U20: 0 | V20: 0 | W20: 0 | X20: 0 | Y20: 0 | Z20: 0 | AA20: 0
B21: Caja Operaciones (acum.) | C21: 0 | D21: 0 | E21: 11538.16 | F21: 11487.96 | G21: 14346.86 | H21: 14346.86 | I21: 14346.86 | J21: 14346.86 | K21: 14330.36 | L21: 14330.36 | M21: 14330.36 | N21: 14330.36 | O21: 14330.36 | P21: 0 | Q21: 0 | R21: 0 | S21: 0 | T21: 0 | U21: 0 | V21: 0 | W21: 0 | X21: 0 | Y21: 0 | Z21: 0 | AA21: 0 | AB21: 0
B22: Gastos generales
B23: Act. Ganadera | C23: -5295.41 | D23: -12564.86 | E23: -10574.68 | F23: -48375.95 | G23: -31144.988 | H23: -7833.02 | I23: -9072.2 | J23: -9847.07 | K23: -13520.65 | L23: -16253.92 | M23: -25828.97 | N23: -91147.8 | O23: -281459.52 | P23: -6553.13 | Q23: -56284.99 | R23: -26352.11 | S23: -13966.47 | T23: -7422.86 | U23: -4859.62 | V23: -12986.37 | W23: -9095.36 | X23: -13334.45 | Y23: -12310.01 | Z23: -6970.36 | AA23: -6597.86 | AB23: -176733.59
B25: Caja Operaciones (mes) | C25: -5295.41 | D25: -12564.86 | E25: -10574.68 | F25: -48375.95 | G25: -31144.988 | H25: -7833.02 | I25: -9072.2 | J25: -9847.07 | K25: -13520.65 | L25: -16253.92 | M25: -25828.97 | N25: -91147.8 | P25: -6553.13 | Q25: -56284.99 | R25: -26352.11 | S25: -13966.47 | T25: -7422.86 | U25: -4859.62 | V25: -12986.37 | W25: -9095.36 | X25: -13334.45 | Y25: -12310.01 | Z25: -6970.36 | AA25: -6597.86
B26: Caja Inversiones (acum.) | C26: -5295.41 | D26: -17860.27 | E26: -28434.95 | F26: -76810.9 | G26: -107955.89 | H26: -115788.91 | I26: -124861.11 | J26: -134708.18 | K26: -148228.83 | L26: -164482.75 | M26: -190311.72 | N26: -281459.52 | O26: -281459.52 | P26: -6553.13 | Q26: -62838.12 | R26: -89190.23 | S26: -103156.7 | T26: -110579.56 | U26: -115439.18 | V26: -128425.55 | W26: -137520.91 | X26: -150855.36 | Y26: -163165.37 | Z26: -170135.73 | AA26: -176733.59 | AB26: -176733.59
B27: Inversiones
B28: Act. Ganadera | C28: 0 | D28: 0 | E28: 0 | F28: 0 | G28: -544.5 | H28: -10393.93 | I28: 0 | J28: -1739.155 | K28: -4112.9 | L28: 0 | M28: 0 | N28: 0 | O28: -16790.485 | P28: 0 | Q28: 0 | R28: 0 | S28: 0 | T28: 0 | U28: 0 | V28: 0 | W28: 0 | X28: 0 | Y28: 0 | Z28: 0 | AA28: 0 | AB28: 0
B30: Caja Inversiones (mes) | C30: 0 | D30: 0 | E30: 0 | F30: 0 | G30: -544.5 | H30: -10393.93 | I30: 0 | J30: -1739.155 | K30: -4112.9 | L30: 0 | M30: 0 | N30: 0 | P30: 0 | Q30: 0 | R30: 0 | S30: 0 | T30: 0 | U30: 0 | V30: 0 | W30: 0 | X30: 0 | Y30: 0 | Z30: 0 | AA30: 0
B31: Caja Inversiones (acum.) | C31: 0 | D31: 0 | E31: 0 | F31: 0 | G31: -544.5 | H31: -10938.43 | I31: -10938.43 | J31: -12677.585 | K31: -16790.485 | L31: -16790.485 | M31: -16790.485 | N31: -16790.485 | O31: -16790.485 | P31: 0 | Q31: 0 | R31: 0 | S31: 0 | T31: 0 | U31: 0 | V31: 0 | W31: 0 | X31: 0 | Y31: 0 | Z31: 0 | AA31: 0 | AB31: 0
B32: Financiación | C32: 743.05 | D32: 9000 | E32: 0 | F32: 0 | G32: 0 | H32: 0 | I32: 0 | J32: 0 | K32: 0 | L32: 0 | M32: 0 | N32: 0 | O32: 9743.05 | P32: 0 | Q32: 30000 | R32: 0 | S32: 0 | T32: -30000 | U32: 0 | V32: 0 | W32: 0 | X32: 0 | Y32: 0 | Z32: 0 | AA32: 0 | AB32: 0
B34: Caja Financiación (mes) | C34: 743.05 | D34: 9000 | E34: 0 | F34: 0 | G34: 0 | H34: 0 | I34: 0 | J34: 0 | K34: 0 | L34: 0 | M34: 0 | N34: 0 | P34: 0 | Q34: 30000 | R34: 0 | S34: 0 | T34: -30000 | U34: 0 | V34: 0 | W34: 0 | X34: 0 | Y34: 0 | Z34: 0 | AA34: 0
B35: Caja Financiación (acum.) | C35: 743.05 | D35: 9743.05 | E35: 9743.05 | F35: 9743.05 | G35: 9743.05 | H35: 9743.05 | I35: 9743.05 | J35: 9743.05 | K35: 9743.05 | L35: 9743.05 | M35: 9743.05 | N35: 9743.05 | O35: 9743.05 | P35: 0 | Q35: 30000 | R35: 30000 | S35: 30000 | T35: 0 | U35: 0 | V35: 0 | W35: 0 | X35: 0 | Y35: 0 | Z35: 0 | AA35: 0 | AB35: 0
B37: Caja opex, capex y serv. deuda | C37: 260.89 | D37: 27213.36 | E37: 53816.9 | F37: -48641.77 | G37: 4896.6782 | H37: -20153.35 | I37: -8615.5979 | J37: 39110.465 | K37: 56022.31 | L37: 17898.77 | M37: -32573.79 | N37: -69953.2 | O37: 19281.665 | P37: 12477.52 | Q37: -13012.31 | R37: -13302.42 | S37: -1785.74 | T37: 2842.0964 | U37: 6383.81 | V37: -690.18 | W37: -2580.92 | X37: 7691.55 | Y37: 46430.99 | Z37: 65468.23 | AA37: 6591.14 | AB37: 116513.77
B38: Check | O38: 0 | AB38: 0
B39: Total circulante
B41: Caja consolidada (mes) | C41: 260.89 | D41: 27213.36 | E41: 53816.9 | F41: -48641.77 | G41: 4896.6782 | H41: -20153.35 | I41: -8615.5979 | J41: 39110.465 | K41: 56022.31 | L41: 17898.77 | M41: -32573.79 | N41: -69953.2 | P41: 12477.52 | Q41: -13012.31 | R41: -13302.42 | S41: -1785.74 | T41: 2842.0964 | U41: 6383.81 | V41: -690.18 | W41: -2580.92 | X41: 7691.55 | Y41: 46430.99 | Z41: 65468.23 | AA41: 6591.14
B42: Caja consolidada (acumulada) | C42: 260.89 | D42: 27474.25 | E42: 81291.15 | F42: 32649.38 | G42: 37546.058 | H42: 17392.708 | I42: 8777.1103 | J42: 47887.575 | K42: 103909.89 | L42: 121808.66 | M42: 89234.865 | N42: 19281.665 | P42: 12477.52 | Q42: -534.79 | R42: -13837.21 | S42: -15622.95 | T42: -12780.854 | U42: -6397.0436 | V42: -7087.2236 | W42: -9668.1436 | X42: -1976.5936 | Y42: 44454.396 | Z42: 109922.63 | AA42: 116513.77
B44: Saldo Inicial | C44: 1178.6 | D44: 1439.49 | E44: 28652.85 | F44: 82469.75 | G44: 33827.98 | H44: 38724.658 | I44: 18571.308 | J44: 9955.7103 | K44: 49066.175 | L44: 105088.49 | M44: 122987.26 | N44: 90413.465 | P44: 20460.265 | Q44: 32937.785 | R44: 19925.475 | S44: 6623.0553 | T44: 4837.3153 | U44: 7679.4117 | V44: 14063.222 | W44: 13373.042 | X44: 10792.122 | Y44: 18483.672 | Z44: 64914.662 | AA44: 130382.89
B45: Caja consolidada | C45: 260.89 | D45: 27213.36 | E45: 53816.9 | F45: -48641.77 | G45: 4896.6782 | H45: -20153.35 | I45: -8615.5979 | J45: 39110.465 | K45: 56022.31 | L45: 17898.77 | M45: -32573.79 | N45: -69953.2 | P45: 12477.52 | Q45: -13012.31 | R45: -13302.42 | S45: -1785.74 | T45: 2842.0964 | U45: 6383.81 | V45: -690.18 | W45: -2580.92 | X45: 7691.55 | Y45: 46430.99 | Z45: 65468.23 | AA45: 6591.14
B46: Saldo final | C46: 1439.49 | D46: 28652.85 | E46: 82469.75 | F46: 33827.98 | G46: 38724.658 | H46: 18571.308 | I46: 9955.7103 | J46: 49066.175 | K46: 105088.49 | L46: 122987.26 | M46: 90413.465 | N46: 20460.265 | P46: 32937.785 | Q46: 19925.475 | R46: 6623.0553 | S46: 4837.3153 | T46: 7679.4117 | U46: 14063.222 | V46: 13373.042 | W46: 10792.122 | X46: 18483.672 | Y46: 64914.662 | Z46: 130382.89 | AA46: 136974.03
B47: Saldos bancarios
B48: Saldo Caixa EUR | C48: 1449.16 | D48: 29148.21 | E48: 82883.58 | F48: 34241.81 | G48: 36138.49 | H48: 16786.84 | I48: 8792.55 | J48: 47903.01 | K48: 74324.32 | L48: 90946.35 | M48: 56483.26 | N48: 18021.45 | P48: 921 | Q48: 0 | R48: 0 | S48: 0 | T48: 0 | U48: 0 | V48: 0 | W48: 0 | X48: 0 | Y48: 0 | Z48: 0 | AA48: 0
B49: Saldo Caja Rural | C49: -9.67 | D49: -27.86 | E49: 53.67 | F49: 53.67 | G49: 53.67 | H49: 51.97 | I49: 105.67 | J49: 105.67 | K49: 28726.67 | L49: 30003.41 | M49: 31892.71 | N49: 401.32 | P49: 29979.29 | Q49: 0 | R49: 0 | S49: 0 | T49: 0 | U49: 0 | V49: 0 | W49: 0 | X49: 0 | Y49: 0 | Z49: 0 | AA49: 0
B50: Saldo Caja | C50: 0 | D50: -467.5 | E50: -467.5 | F50: -467.5 | G50: 2532.5 | H50: 1732.5 | I50: 1057.5 | J50: 1057.5 | K50: 2037.5 | L50: 2037.5 | M50: 2037.5 | N50: 2037.5 | P50: 2037.5 | Q50: 0 | R50: 0 | S50: 0 | T50: 0 | U50: 0 | V50: 0 | W50: 0 | X50: 0 | Y50: 0 | Z50: 0 | AA50: 0
...

Sheet Animales
K3: Avance
C4: Presupuesto | E4: Avance | F4: 46112 | J4: Presupuesto | K4: 46112
C5: Animales | D5: % | E5: Animales | F5: % | J5: Animales | K5: Animales
B6: Madres fértiles | C6: 158 | D6: 1 | E6: 191 | F6: 1 | I6: Madres | J6: 30 | K6: 29
B7: Partos | C7: 147 | D7: =+C7/C6 -> 0.93037975 | E7: 138 | F7: =+E7/$E$6 -> 0.72251309 | I7: lechones/madre | J7: 6 | K7: =5.517 -> 5.517
B8: Terneros de 200kg | C8: =+C7-5 -> 142 | D8: =+C8/$C$6 -> 0.89873418 | E8: 138 | F8: =+E8/$E$6 -> 0.72251309 | I8: Partos | J8: =+J6*J7*2 -> 360 | K8: =+K6*K7*2 -> 319.986
B9: A venta | C9: 142 | D9: =+C9/$C$6 -> 0.89873418 | E9: 71 | F9: =+E9/$E$6 -> 0.37172775 | I9: Muertes | J9: 60 | K9: 0
B10: A cebo intermedio/remate | C10: 0 | D10: =+C10/$C$6 -> 0 | E10: 6 | F10: =+E10/$E$6 -> 0.031413613 | I10: lechones a término | J10: =+J8-J9 -> 300 | K10: =+K8-K9 -> 319.986
B11: A recría | C11: 0 | D11: =+C11/$C$6 -> 0 | E11: 49 | F11: =+E11/$E$6 -> 0.2565445 | I11: lechones | J11: 300 | K11: 320
B12: Total | C12: =SUM(C9:C11) -> 142 | D12: =+C12/$C$6 -> 0.89873418 | E12: =SUM(E9:E11) -> 126 | F12: =+E12/$E$6 -> 0.65968586 | I12: Marranos y primales | J12: 111 | K12: =128+95 -> 223 | L12: Baja de 32 marranos escapados
I13: Montanera | J13: =SUM(J14:J15) -> 287 | K13: =SUM(K14:K15) -> 277
B14: Ventas 200kg | C14: 85 | E14: 71 | I14: Propia | J14: 87 | K14: =86-4+6-5 -> 83
B15: Ventas remate | C15: =2+31 -> 33 | E15: 9 | I15: Terceros | J15: 200 | K15: =200-6 -> 194
B16: Total general | C16: =SUM(C14:C15) -> 118 | E16: =SUM(E14:E15) -> 80 | I16: Total | J16: =+J11+J12+J13 -> 698 | K16: =+K11+K12+K13 -> 820
I17: Maquila propía | K17: =43 -> 43
I18: Maquila terceros | K18: 3

Sheet Consolidado
C1: 2023/2024 | P1: 2024/2025 | AC1: 2025/2026 | AS1: 2026/2027
C2: Sep | D2: Oct | E2: Nov | F2: Dic | G2: Ene | H2: Feb | I2: Mar | J2: Abr | K2: May | L2: Jun | M2: Jul | N2: Ago | O2: Totales | P2: Sep | Q2: Oct | R2: Nov | S2: Dic | T2: Ene | U2: Feb | V2: Mar | W2: Abr | X2: May | Y2: Jun | Z2: Jul | AA2: Ago | AB2: Totales | AC2: Sep | AD2: Oct | AE2: Nov | AF2: Dic | AG2: Ene | AH2: Feb | AI2: Mar | AJ2: Abr | AK2: May | AL2: Jun | AM2: Jul | AN2: Ago | AO2: Totales | AS2: Sep | AT2: Oct | AU2: Nov | AV2: Dic | AW2: Ene | AX2: Feb | AY2: Mar | AZ2: Abr | BA2: May | BB2: Jun | BC2: Jul | BD2: Ago | BE2: Totales
B3: Vacuno
B4: Cobros | C4: ='Ing y gtos'!AE16 -> 556.3 | D4: ='Ing y gtos'!AF16 -> 33077.51 | E4: ='Ing y gtos'!AG16 -> 51305.32 | F4: ='Ing y gtos'!AH16 -> 0 | G4: ='Ing y gtos'!AI16 -> 37253.67 | H4: ='Ing y gtos'!AJ16 -> 0 | I4: ='Ing y gtos'!AK16 -> 0 | J4: ='Ing y gtos'!AL16 -> 24907.2 | ... N4: ='Ing y gtos'!AP16 -> 17183.67 | O4: =SUM(C4:N4) -> 218587.1 | P4: ='Ing y gtos'!AU16 -> 20013.44 | Q4: ='Ing y gtos'!AV16 -> 26949.06 | R4: ='Ing y gtos'!AW16 -> 315 | S4: ='Ing y gtos'!AX16 -> 12466.31 | T4: ='Ing y gtos'!AY16 -> 7989.53 | U4: ='Ing y gtos'!AZ16 -> 0 | V4: ='Ing y gtos'!BA16 -> 10410.67 | W4: ='Ing y gtos'!BB16 -> 11634.21 | ... AA4: ='Ing y gtos'!BF16 -> 24335.96 | AB4: =SUM(P4:AA4) -> 120683.72 | AC4: ='Ing y gtos'!BJ16 -> 8092.83 | AD4: ='Ing y gtos'!BK16 -> 29566.61 | AE4: ='Ing y gtos'!BL16 -> 35506.83 | AF4: ='Ing y gtos'!BM16 -> 5514.23 | AG4: ='Ing y gtos'!BN16 -> 8798.9 | AH4: ='Ing y gtos'!BO16 -> 0 | AI4: ='Ing y gtos'!BP16 -> 7620.43 | AJ4: ='Ing y gtos'!BQ16 -> 276.39 | ... AN4: ='Ing y gtos'!BU16 -> 28490.25 | AO4: =SUM(AC4:AN4) -> 176294.96 | AS4: ='Ing y gtos'!BY16 -> 5927.5 | AT4: ='Ing y gtos'!BZ16 -> 36282.5 | AU4: ='Ing y gtos'!CA16 -> 21097 | AV4: ='Ing y gtos'!CB16 -> 31411.5 | AW4: ='Ing y gtos'!CC16 -> 1185.5 | AX4: ='Ing y gtos'!CD16 -> 5927.5 | AY4: ='Ing y gtos'!CE16 -> 4742 | AZ4: ='Ing y gtos'!CF16 -> 2371 | ... BD4: ='Ing y gtos'!CJ16 -> 35517.58 | BE4: =SUM(AS4:BD4) -> 207530.68
B5: Pagos | C5: ='Ing y gtos'!AE33 -> 0 | D5: ='Ing y gtos'!AF33 -> 0 | E5: ='Ing y gtos'!AG33 -> 2310.58 | F5: ='Ing y gtos'!AH33 -> 836.06 | G5: ='Ing y gtos'!AI33 -> 5019.7136 | H5: ='Ing y gtos'!AJ33 -> 16.5 | I5: ='Ing y gtos'!AK33 -> 350 | J5: ='Ing y gtos'!AL33 -> 2104.36 | ... N5: ='Ing y gtos'!AP33 -> 791.98 | O5: =SUM(C5:N5) -> 15767.024 | P5: ='Ing y gtos'!AU33 -> 705.64 | Q5: ='Ing y gtos'!AV33 -> 2112.36 | R5: ='Ing y gtos'!AW33 -> -2118.78 | S5: ='Ing y gtos'!AX33 -> 1585.65 | T5: ='Ing y gtos'!AY33 -> 2063.23 | U5: ='Ing y gtos'!AZ33 -> -2875.88 | V5: ='Ing y gtos'!BA33 -> 1496.17 | W5: ='Ing y gtos'!BB33 -> 10323 | ... AA5: ='Ing y gtos'!BF33 -> 2493.1 | AB5: =SUM(P5:AA5) -> 10893.02 | AC5: ='Ing y gtos'!BJ33 -> 8.93 | AD5: ='Ing y gtos'!BK33 -> 4924.88 | AE5: ='Ing y gtos'!BL33 -> 1939.36 | AF5: ='Ing y gtos'!BM33 -> 1243.61 | AG5: ='Ing y gtos'!BN33 -> 1931.2 | AH5: ='Ing y gtos'!BO33 -> -1902.68 | AI5: ='Ing y gtos'!BP33 -> 1921.29 | AJ5: ='Ing y gtos'!BQ33 -> 1054.16 | ... AN5: ='Ing y gtos'!BU33 -> 1960 | AO5: =SUM(AC5:AN5) -> 21220.57 | AS5: ='Ing y gtos'!BY33 -> 600 | AT5: ='Ing y gtos'!BZ33 -> 2961.41 | AU5: ='Ing y gtos'!CA33 -> 600 | AV5: ='Ing y gtos'!CB33 -> 900 | AW5: ='Ing y gtos'!CC33 -> 4137.59 | AX5: ='Ing y gtos'!CD33 -> 600 | AY5: ='Ing y gtos'!CE33 -> 1300 | AZ5: ='Ing y gtos'!CF33 -> 1874.56 | ... BD5: ='Ing y gtos'!CJ33 -> 1760 | BE5: =SUM(AS5:BD5) -> 19094.97
B7: Caja Operaciones (mes) | C7: =C4-C5 -> 556.3 | D7: =D4-D5 -> 33077.51 | E7: =E4-E5 -> 48994.74 | F7: =F4-F5 -> -836.06 | G7: =G4-G5 -> 32233.956 | H7: =H4-H5 -> -16.5 | I7: =I4-I5 -> -350 | J7: =J4-J5 -> 22802.84 | ... N7: =N4-N5 -> 16391.69 | P7: =P4-P5 -> 19307.8 | Q7: =Q4-Q5 -> 24836.7 | R7: =R4-R5 -> 2433.78 | S7: =S4-S5 -> 10880.66 | T7: =T4-T5 -> 5926.3 | U7: =U4-U5 -> 2875.88 | V7: =V4-V5 -> 8914.5 | W7: =W4-W5 -> 1311.21 | ... AA7: =AA4-AA5 -> 21842.86 | AC7: =AC4-AC5 -> 8083.9 | AD7: =AD4-AD5 -> 24641.73 | AE7: =AE4-AE5 -> 33567.47 | AF7: =AF4-AF5 -> 4270.62 | AG7: =AG4-AG5 -> 6867.7 | AH7: =AH4-AH5 -> 1902.68 | AI7: =AI4-AI5 -> 5699.14 | AJ7: =AJ4-AJ5 -> -777.77 | ... AN7: =AN4-AN5 -> 26530.25 | AS7: =AS4-AS5 -> 5327.5 | AT7: =AT4-AT5 -> 33321.09 | AU7: =AU4-AU5 -> 20497 | AV7: =AV4-AV5 -> 30511.5 | AW7: =AW4-AW5 -> -2952.09 | AX7: =AX4-AX5 -> 5327.5 | AY7: =AY4-AY5 -> 3442 | AZ7: =AZ4-AZ5 -> 496.44 | ... BD7: =BD4-BD5 -> 33757.58
B8: Caja Operaciones (acum.) | C8: =C7 -> 556.3 | D8: =D7+C8 -> 33633.81 | E8: =E7+D8 -> 82628.55 | F8: =F7+E8 -> 81792.49 | G8: =G7+F8 -> 114026.45 | H8: =H7+G8 -> 114009.95 | I8: =I7+H8 -> 113659.95 | J8: =J7+I8 -> 136462.79 | K8: =K7+J8 -> 168628.59 | ... N8: =N7+M8 -> 202820.08 | O8: =O4-O5 -> 202820.08 | P8: =P7 -> 19307.8 | Q8: =Q7+P8 -> 44144.5 | R8: =R7+Q8 -> 46578.28 | S8: =S7+R8 -> 57458.94 | T8: =T7+S8 -> 63385.24 | U8: =U7+T8 -> 66261.12 | V8: =V7+U8 -> 75175.62 | W8: =W7+V8 -> 76486.83 | X8: =X7+W8 -> 85276.43 | ... AA8: =AA7+Z8 -> 109790.7 | AB8: =AB4-AB5 -> 109790.7 | AC8: =AC7 -> 8083.9 | AD8: =AD7+AC8 -> 32725.63 | AE8: =AE7+AD8 -> 66293.1 | AF8: =AF7+AE8 -> 70563.72 | AG8: =AG7+AF8 -> 77431.42 | AH8: =AH7+AG8 -> 79334.1 | AI8: =AI7+AH8 -> 85033.24 | AJ8: =AJ7+AI8 -> 84255.47 | AK8: =AK7+AJ8 -> 87308.63 | ... AN8: =AN7+AM8 -> 155074.39 | AO8: =AO4-AO5 -> 155074.39 | AS8: =AS7 -> 5327.5 | AT8: =AT7+AS8 -> 38648.59 | AU8: =AU7+AT8 -> 59145.59 | AV8: =AV7+AU8 -> 89657.09 | AW8: =AW7+AV8 -> 86705 | AX8: =AX7+AW8 -> 92032.5 | AY8: =AY7+AX8 -> 95474.5 | AZ8: =AZ7+AY8 -> 95970.94 | BA8: =BA7+AZ8 -> 114338.94 | ... BD8: =BD7+BC8 -> 188435.71 | BE8: =BE4-BE5 -> 188435.71
B9: Porcino
B10: Cobros | C10: ='Ing y gtos'!AE42 -> 4256.95 | D10: ='Ing y gtos'!AF42 -> 280.97 | E10: ='Ing y gtos'!AG42 -> 7918.95 | F10: ='Ing y gtos'!AH42 -> 5851.53 | G10: ='Ing y gtos'!AI42 -> 6817.68 | H10: ='Ing y gtos'!AJ42 -> 1725.36 | I10: ='Ing y gtos'!AK42 -> 2334.57 | J10: ='Ing y gtos'!AL42 -> 34055.67 | ... N10: ='Ing y gtos'!AP42 -> 7039.33 | O10: =SUM(C10:N10) -> 140332.76 | P10: ='Ing y gtos'!AU42 -> 1689.99 | Q10: ='Ing y gtos'!AV42 -> 5922.68 | R10: ='Ing y gtos'!AW42 -> 1825.73 | S10: ='Ing y gtos'!AX42 -> 3923.39 | T10: ='Ing y gtos'!AY42 -> 3567.39 | U10: ='Ing y gtos'!AZ42 -> 20249.95 | V10: ='Ing y gtos'!BA42 -> 18215.37 | W10: ='Ing y gtos'!BB42 -> 53326 | ... AA10: ='Ing y gtos'!BF42 -> 8485.09 | AB10: =SUM(P10:AA10) -> 144911.39 | AC10: ='Ing y gtos'!BJ42 -> 3918.04 | AD10: ='Ing y gtos'!BK42 -> 6447.53 | AE10: ='Ing y gtos'!BL42 -> 4972.37 | AF10: ='Ing y gtos'!BM42 -> 5951.74 | AG10: ='Ing y gtos'!BN42 -> 3440.39 | AH10: ='Ing y gtos'!BO42 -> 31356.42 | AI10: ='Ing y gtos'!BP42 -> 4000.67 | AJ10: ='Ing y gtos'!BQ42 -> 58156.46 | ... AN10: ='Ing y gtos'!BU42 -> 6321.49 | AO10: =SUM(AC10:AN10) -> 142778.8 | AS10: ='Ing y gtos'!BY42 -> 0 | AT10: ='Ing y gtos'!BZ42 -> 0 | AU10: ='Ing y gtos'!CA42 -> 0 | AV10: ='Ing y gtos'!CB42 -> 0 | AW10: ='Ing y gtos'!CC42 -> 0 | AX10: ='Ing y gtos'!CD42 -> 31824 | AY10: ='Ing y gtos'!CE42 -> 63648 | AZ10: ='Ing y gtos'!CF42 -> 31824 | ... BD10: ='Ing y gtos'!CJ42 -> 0 | BE10: =SUM(AS10:BD10) -> 143296
B11: Pagos | C11: ='Ing y gtos'!AE54 -> 0 | D11: ='Ing y gtos'!AF54 -> 2580.26 | E11: ='Ing y gtos'!AG54 -> 4060.27 | F11: ='Ing y gtos'!AH54 -> 5231.09 | G11: ='Ing y gtos'!AI54 -> 6014.37 | H11: ='Ing y gtos'!AJ54 -> 3635.26 | I11: ='Ing y gtos'!AK54 -> 1494.8879 | J11: ='Ing y gtos'!AL54 -> 6161.82 | ... N11: ='Ing y gtos'!AP54 -> 2308.35 | O11: =SUM(C11:N11) -> 50274.578 | P11: ='Ing y gtos'!AU54 -> 1967.14 | Q11: ='Ing y gtos'!AV54 -> 48.39 | R11: ='Ing y gtos'!AW54 -> 4608.29 | S11: ='Ing y gtos'!AX54 -> 3678.43 | T11: ='Ing y gtos'!AY54 -> 4127.2 | U11: ='Ing y gtos'!AZ54 -> 1865.58 | V11: ='Ing y gtos'!BA54 -> 1951.96 | W11: ='Ing y gtos'!BB54 -> 7250.01 | ... AA11: ='Ing y gtos'!BF54 -> 4600.94 | AB11: =SUM(P11:AA11) -> 47961.9 | AC11: ='Ing y gtos'!BJ54 -> 362.52 | AD11: ='Ing y gtos'!BK54 -> 8388.63 | AE11: ='Ing y gtos'!BL54 -> 10129.1 | AF11: ='Ing y gtos'!BM54 -> 9859.88 | AG11: ='Ing y gtos'!BN54 -> 3139.49 | AH11: ='Ing y gtos'!BO54 -> 7828.47 | AI11: ='Ing y gtos'!BP54 -> 6049.99 | AJ11: ='Ing y gtos'!BQ54 -> 6219.26 | ... AN11: ='Ing y gtos'!BU54 -> 1700 | AO11: =SUM(AC11:AN11) -> 67635.44 | AS11: ='Ing y gtos'!BY54 -> 750 | AT11: ='Ing y gtos'!BZ54 -> 250 | AU11: ='Ing y gtos'!CA54 -> 1750 | AV11: ='Ing y gtos'!CB54 -> 750 | AW11: ='Ing y gtos'!CC54 -> 750 | AX11: ='Ing y gtos'!CD54 -> 250 | AY11: ='Ing y gtos'!CE54 -> 250 | AZ11: ='Ing y gtos'!CF54 -> 2250 | ... BD11: ='Ing y gtos'!CJ54 -> 250 | BE11: =SUM(AS11:BD11) -> 8000
B13: Caja Operaciones (mes) | C13: =C10-C11 -> 4256.95 | D13: =D10-D11 -> -2299.29 | E13: =E10-E11 -> 3858.68 | F13: =F10-F11 -> 620.44 | G13: =G10-G11 -> 803.31 | H13: =H10-H11 -> -1909.9 | I13: =I10-I11 -> 839.6821 | J13: =J10-J11 -> 27893.85 | ... N13: =N10-N11 -> 4730.98 | P13: =P10-P11 -> -277.15 | Q13: =Q10-Q11 -> 5874.29 | R13: =R10-R11 -> -2782.56 | S13: =S10-S11 -> 244.96 | T13: =T10-T11 -> -559.81 | U13: =U10-U11 -> 18384.37 | V13: =V10-V11 -> 16263.41 | W13: =W10-W11 -> 46075.99 | ... AA13: =AA10-AA11 -> 3884.15 | AC13: =AC10-AC11 -> 3555.52 | AD13: =AD10-AD11 -> -1941.1 | AE13: =AE10-AE11 -> -5156.73 | AF13: =AF10-AF11 -> -3908.14 | AG13: =AG10-AG11 -> 300.9 | AH13: =AH10-AH11 -> 23527.95 | AI13: =AI10-AI11 -> -2049.32 | AJ13: =AJ10-AJ11 -> 51937.2 | ... AN13: =AN10-AN11 -> 4621.49 | AS13: =AS10-AS11 -> -750 | AT13: =AT10-AT11 -> -250 | AU13: =AU10-AU11 -> -1750 | AV13: =AV10-AV11 -> -750 | AW13: =AW10-AW11 -> -750 | AX13: =AX10-AX11 -> 31574 | AY13: =AY10-AY11 -> 63398 | AZ13: =AZ10-AZ11 -> 29574 | ... BD13: =BD10-BD11 -> -250
B14: Caja Operaciones (acum.) | C14: =C13 -> 4256.95 | D14: =D13+C14 -> 1957.66 | E14: =E13+D14 -> 5816.34 | F14: =F13+E14 -> 6436.78 | G14: =G13+F14 -> 7240.09 | H14: =H13+G14 -> 5330.19 | I14: =I13+H14 -> 6169.8721 | J14: =J13+I14 -> 34063.722 | K14: =K13+J14 -> 75680.282 | ... N14: =N13+M14 -> 90058.182 | O14: =O10-O11 -> 90058.182 | P14: =P13 -> -277.15 | Q14: =Q13+P14 -> 5597.14 | R14: =R13+Q14 -> 2814.58 | S14: =S13+R14 -> 3059.54 | T14: =T13+S14 -> 2499.73 | U14: =U13+T14 -> 20884.1 | V14: =V13+U14 -> 37147.51 | W14: =W13+V14 -> 83223.5 | X14: =X13+W14 -> 92182.93 | ... AA14: =AA13+Z14 -> 96949.49 | AB14: =AB10-AB11 -> 96949.49 | AC14: =AC13 -> 3555.52 | AD14: =AD13+AC14 -> 1614.42 | AE14: =AE13+AD14 -> -3542.31 | AF14: =AF13+AE14 -> -7450.45 | AG14: =AG13+AF14 -> -7149.55 | AH14: =AH13+AG14 -> 16378.4 | AI14: =AI13+AH14 -> 14329.08 | AJ14: =AJ13+AI14 -> 66266.28 | AK14: =AK13+AJ14 -> 64035.35 | ... AN14: =AN13+AM14 -> 75143.36 | AO14: =AO10-AO11 -> 75143.36 | AS14: =AS13 -> -750 | AT14: =AT13+AS14 -> -1000 | AU14: =AU13+AT14 -> -2750 | AV14: =AV13+AU14 -> -3500 | AW14: =AW13+AV14 -> -4250 | AX14: =AX13+AW14 -> 27324 | AY14: =AY13+AX14 -> 90722 | AZ14: =AZ13+AY14 -> 120296 | BA14: =BA13+AZ14 -> 128046 | ... BD14: =BD13+BC14 -> 135296 | BE14: =BE10-BE11 -> 135296
B15: Ovino
B16: Cobros | C16: ='Ing y gtos'!AE65 -> 0 | D16: ='Ing y gtos'!AF65 -> 0 | E16: ='Ing y gtos'!AG65 -> 11902 | F16: ='Ing y gtos'!AH65 -> 0 | G16: ='Ing y gtos'!AI65 -> 2858.9 | H16: ='Ing y gtos'!AJ65 -> 0 | I16: ='Ing y gtos'!AK65 -> 0 | J16: ='Ing y gtos'!AL65 -> 0 | ... N16: ='Ing y gtos'!AP65 -> 0 | O16: =SUM(C16:N16) -> 15735.9 | P16: ='Ing y gtos'!AU61 -> 0 | Q16: ='Ing y gtos'!AV61 -> 0 | R16: ='Ing y gtos'!AW61 -> 0 | S16: ='Ing y gtos'!AX61 -> 0 | T16: ='Ing y gtos'!AY61 -> 180 | U16: ='Ing y gtos'!AZ61 -> 0 | V16: ='Ing y gtos'!BA61 -> 0 | W16: ='Ing y gtos'!BB61 -> 1232 | ... AA16: ='Ing y gtos'!BF61 -> 0 | AB16: =SUM(P16:AA16) -> 1412 | AC16: ='Ing y gtos'!BJ61 -> 0 | AD16: ='Ing y gtos'!BK61 -> 0 | AE16: ='Ing y gtos'!BL61 -> 0 | AF16: ='Ing y gtos'!BM61 -> 365 | AG16: ='Ing y gtos'!BN61 -> 0 | AH16: ='Ing y gtos'!BO61 -> 400 | AI16: ='Ing y gtos'!BP61 -> 0 | AJ16: ='Ing y gtos'!BQ61 -> 1045 | ... AN16: ='Ing y gtos'!BU61 -> 0 | AO16: =SUM(AC16:AN16) -> 1810 | AS16: ='Ing y gtos'!BY61 -> 0 | AT16: ='Ing y gtos'!BZ61 -> 0 | AU16: ='Ing y gtos'!CA61 -> 0 | AV16: ='Ing y gtos'!CB61 -> 0 | AW16: ='Ing y gtos'!CC61 -> 0 | AX16: ='Ing y gtos'!CD61 -> 0 | AY16: ='Ing y gtos'!CE61 -> 0 | AZ16: ='Ing y gtos'!CF61 -> 0 | ... BD16: ='Ing y gtos'!CJ61 -> 0 | BE16: =SUM(AS16:BD16) -> 0
B17: Pagos | C17: ='Ing y gtos'!AE73 -> 0 | D17: ='Ing y gtos'!AF73 -> 0 | E17: ='Ing y gtos'!AG73 -> 363.84 | F17: ='Ing y gtos'!AH73 -> 50.2 | G17: ='Ing y gtos'!AI73 -> 0 | H17: ='Ing y gtos'!AJ73 -> 0 | I17: ='Ing y gtos'!AK73 -> 0 | J17: ='Ing y gtos'!AL73 -> 0 | ... N17: ='Ing y gtos'!AP73 -> 0 | O17: =SUM(C17:N17) -> 430.54 | P17: ='Ing y gtos'!AU73 -> 0 | Q17: ='Ing y gtos'!AV73 -> 0 | R17: ='Ing y gtos'!AW73 -> 0 | S17: ='Ing y gtos'!AX73 -> 0 | T17: ='Ing y gtos'!AY73 -> 57.2 | U17: ='Ing y gtos'!AZ73 -> 0 | V17: ='Ing y gtos'!BA73 -> 0 | W17: ='Ing y gtos'!BB73 -> 0 | ... AA17: ='Ing y gtos'!BF73 -> 94.6 | AB17: =SUM(P17:AA17) -> 271.8 | AC17: ='Ing y gtos'!BJ73 -> 0 | AD17: ='Ing y gtos'!BK73 -> 0 | AE17: ='Ing y gtos'!BL73 -> 0 | AF17: ='Ing y gtos'!BM73 -> 0 | AG17: ='Ing y gtos'!BN73 -> 0 | AH17: ='Ing y gtos'!BO73 -> 0 | AI17: ='Ing y gtos'!BP73 -> 0 | AJ17: ='Ing y gtos'!BQ73 -> 0 | ... AN17: ='Ing y gtos'!BU73 -> 0 | AO17: =SUM(AC17:AN17) -> 0 | AS17: ='Ing y gtos'!BY73 -> 0 | AT17: ='Ing y gtos'!BZ73 -> 0 | AU17: ='Ing y gtos'!CA73 -> 0 | AV17: ='Ing y gtos'!CB73 -> 0 | AW17: ='Ing y gtos'!CC73 -> 0 | AX17: ='Ing y gtos'!CD73 -> 0 | AY17: ='Ing y gtos'!CE73 -> 0 | AZ17: ='Ing y gtos'!CF73 -> 0 | ... BD17: ='Ing y gtos'!CJ73 -> 0 | BE17: =SUM(AS17:BD17) -> 0
B19: Caja Operaciones (mes) | C19: =C16-C17 -> 0 | D19: =D16-D17 -> 0 | E19: =E16-E17 -> 11538.16 | F19: =F16-F17 -> -50.2 | G19: =G16-G17 -> 2858.9 | H19: =H16-H17 -> 0 | I19: =I16-I17 -> 0 | J19: =J16-J17 -> 0 | ... N19: =N16-N17 -> 0 | P19: =P16-P17 -> 0 | Q19: =Q16-Q17 -> 0 | R19: =R16-R17 -> 0 | S19: =S16-S17 -> 0 | T19: =T16-T17 -> 122.8 | U19: =U16-U17 -> 0 | V19: =V16-V17 -> 0 | W19: =W16-W17 -> 1232 | ... AA19: =AA16-AA17 -> -94.6 | AC19: =AC16-AC17 -> 0 | AD19: =AD16-AD17 -> 0 | AE19: =AE16-AE17 -> 0 | AF19: =AF16-AF17 -> 365 | AG19: =AG16-AG17 -> 0 | AH19: =AH16-AH17 -> 400 | AI19: =AI16-AI17 -> 0 | AJ19: =AJ16-AJ17 -> 1045 | ... AN19: =AN16-AN17 -> 0 | AS19: =AS16-AS17 -> 0 | AT19: =AT16-AT17 -> 0 | AU19: =AU16-AU17 -> 0 | AV19: =AV16-AV17 -> 0 | AW19: =AW16-AW17 -> 0 | AX19: =AX16-AX17 -> 0 | AY19: =AY16-AY17 -> 0 | AZ19: =AZ16-AZ17 -> 0 | ... BD19: =BD16-BD17 -> 0
B20: Caja Operaciones (acum.) | C20: =C19 -> 0 | D20: =D19+C20 -> 0 | E20: =E19+D20 -> 11538.16 | F20: =F19+E20 -> 11487.96 | G20: =G19+F20 -> 14346.86 | H20: =H19+G20 -> 14346.86 | I20: =I19+H20 -> 14346.86 | J20: =J19+I20 -> 14346.86 | K20: =K19+J20 -> 14405.36 | ... N20: =N19+M20 -> 15305.36 | O20: =O16-O17 -> 15305.36 | P20: =P19 -> 0 | Q20: =Q19+P20 -> 0 | R20: =R19+Q20 -> 0 | S20: =S19+R20 -> 0 | T20: =T19+S20 -> 122.8 | U20: =U19+T20 -> 122.8 | V20: =V19+U20 -> 122.8 | W20: =W19+V20 -> 1354.8 | X20: =X19+W20 -> 1354.8 | ... AA20: =AA19+Z20 -> 1140.2 | AB20: =AB16-AB17 -> 1140.2 | AC20: =AC19 -> 0 | AD20: =AD19+AC20 -> 0 | AE20: =AE19+AD20 -> 0 | AF20: =AF19+AE20 -> 365 | AG20: =AG19+AF20 -> 365 | AH20: =AH19+AG20 -> 765 | AI20: =AI19+AH20 -> 765 | AJ20: =AJ19+AI20 -> 1810 | AK20: =AK19+AJ20 -> 1810 | ... AN20: =AN19+AM20 -> 1810 | AO20: =AO16-AO17 -> 1810 | AS20: =AS19 -> 0 | AT20: =AT19+AS20 -> 0 | AU20: =AU19+AT20 -> 0 | AV20: =AV19+AU20 -> 0 | AW20: =AW19+AV20 -> 0 | AX20: =AX19+AW20 -> 0 | AY20: =AY19+AX20 -> 0 | AZ20: =AZ19+AY20 -> 0 | BA20: =BA19+AZ20 -> 0 | ... BD20: =BD19+BC20 -> 0 | BE20: =BE16-BE17 -> 0
B21: Gastos generales
B22: Act. Ganadera | C22: =-'Ing y gtos'!AE121 -> -9552.36 | D22: =-'Ing y gtos'!AF121 -> -12097.36 | E22: =-'Ing y gtos'!AG121 -> -10574.68 | F22: =-'Ing y gtos'!AH121 -> -48375.95 | G22: =-'Ing y gtos'!AI121 -> -30644.988 | H22: =-'Ing y gtos'!AJ121 -> -7833.02 | I22: =-'Ing y gtos'!AK121 -> -9105.27 | J22: =-'Ing y gtos'!AL121 -> -10847.08 | ... N22: =-'Ing y gtos'!AP121 -> -91075.87 | O22: =SUM(C22:N22) -> -287843.97 | P22: =-'Ing y gtos'!AU121 -> -6343.13 | Q22: =-'Ing y gtos'!AV121 -> -23399.14 | R22: =-'Ing y gtos'!AW121 -> -41914.55 | S22: =-'Ing y gtos'!AX121 -> -25865.78 | T22: =-'Ing y gtos'!AY121 -> -27367.23 | U22: =-'Ing y gtos'!AZ121 -> -18293.24 | V22: =-'Ing y gtos'!BA121 -> -16871.13 | W22: =-'Ing y gtos'!BB121 -> -31497.31 | ... AA22: =-'Ing y gtos'!BF121 -> -15563.83 | AB22: =SUM(P22:AA22) -> -242893.59 | AC22: =-'Ing y gtos'!BJ121 -> -48879.29 | AD22: =-'Ing y gtos'!BK121 -> -29541.51 | AE22: =-'Ing y gtos'!BL121 -> -31309.26 | AF22: =-'Ing y gtos'!BM121 -> -26855.13 | AG22: =-'Ing y gtos'!BN121 -> -19974.99 | AH22: =-'Ing y gtos'!BO121 -> -15936.72 | AI22: =-'Ing y gtos'!BP121 -> -26195.73 | AJ22: =-'Ing y gtos'!BQ121 -> -8667.63 | ... AN22: =-'Ing y gtos'!BU121 -> -11996.58 | AO22: =SUM(AC22:AN22) -> -291033.99 | AS22: =-'Ing y gtos'!BY121 -> -48628.77 | AT22: =-'Ing y gtos'!BZ121 -> -22319.89 | AU22: =-'Ing y gtos'!CA121 -> -23747.79 | AV22: =-'Ing y gtos'!CB121 -> -33267.47 | AW22: =-'Ing y gtos'!CC121 -> -13804.79 | AX22: =-'Ing y gtos'!CD121 -> -12246.45 | AY22: =-'Ing y gtos'!CE121 -> -13303.84 | AZ22: =-'Ing y gtos'!CF121 -> -13711.51 | ... BD22: =-'Ing y gtos'!CJ121 -> -18763.07 | BE22: =SUM(AS22:BD22) -> -265853.09
B24: Caja Operaciones (mes) | C24: =C22 -> -9552.36 | D24: =D22 -> -12097.36 | E24: =E22 -> -10574.68 | F24: =F22 -> -48375.95 | G24: =G22 -> -30644.988 | H24: =H22 -> -7833.02 | I24: =I22 -> -9105.27 | J24: =J22 -> -10847.08 | ... N24: =N22 -> -91075.87 | P24: =P22 -> -6343.13 | Q24: =Q22 -> -23399.14 | R24: =R22 -> -41914.55 | S24: =S22 -> -25865.78 | T24: =T22 -> -27367.23 | U24: =U22 -> -18293.24 | V24: =V22 -> -16871.13 | W24: =W22 -> -31497.31 | ... AA24: =AA22 -> -15563.83 | AC24: =AC22 -> -48879.29 | AD24: =AD22 -> -29541.51 | AE24: =AE22 -> -31309.26 | AF24: =AF22 -> -26855.13 | AG24: =AG22 -> -19974.99 | AH24: =AH22 -> -15936.72 | AI24: =AI22 -> -26195.73 | AJ24: =AJ22 -> -8667.63 | ... AN24: =AN22 -> -11996.58 | AS24: =AS22 -> -48628.77 | AT24: =AT22 -> -22319.89 | AU24: =AU22 -> -23747.79 | AV24: =AV22 -> -33267.47 | AW24: =AW22 -> -13804.79 | AX24: =AX22 -> -12246.45 | AY24: =AY22 -> -13303.84 | AZ24: =AZ22 -> -13711.51 | ... BD24: =BD22 -> -18763.07
B25: Caja Inversiones (acum.) | C25: =C24 -> -9552.36 | D25: =D24+C25 -> -21649.72 | E25: =E24+D25 -> -32224.4 | F25: =F24+E25 -> -80600.35 | G25: =G24+F25 -> -111245.34 | H25: =H24+G25 -> -119078.36 | I25: =I24+H25 -> -128183.63 | J25: =J24+I25 -> -139030.71 | K25: =K24+J25 -> -153621.36 | ... N25: =N24+M25 -> -287843.97 | O25: =SUM(O22:O23) -> -287843.97 | P25: =P24 -> -6343.13 | Q25: =Q24+P25 -> -29742.27 | R25: =R24+Q25 -> -71656.82 | S25: =S24+R25 -> -97522.6 | T25: =T24+S25 -> -124889.83 | U25: =U24+T25 -> -143183.07 | V25: =V24+U25 -> -160054.2 | W25: =W24+V25 -> -191551.51 | X25: =X24+W25 -> -204786.95 | ... AA25: =AA24+Z25 -> -242893.59 | AB25: =SUM(AB22:AB23) -> -242893.59 | AC25: =AC24 -> -48879.29 | AD25: =AD24+AC25 -> -78420.8 | AE25: =AE24+AD25 -> -109730.06 | AF25: =AF24+AE25 -> -136585.19 | AG25: =AG24+AF25 -> -156560.18 | AH25: =AH24+AG25 -> -172496.9 | AI25: =AI24+AH25 -> -198692.63 | AJ25: =AJ24+AI25 -> -207360.26 | AK25: =AK24+AJ25 -> -237734.78 | ... AN25: =AN24+AM25 -> -291033.99 | AO25: =SUM(AO22:AO23) -> -291033.99 | AS25: =AS24 -> -48628.77 | AT25: =AT24+AS25 -> -70948.66 | AU25: =AU24+AT25 -> -94696.45 | AV25: =AV24+AU25 -> -127963.92 | AW25: =AW24+AV25 -> -141768.71 | AX25: =AX24+AW25 -> -154015.16 | AY25: =AY24+AX25 -> -167319 | AZ25: =AZ24+AY25 -> -181030.51 | BA25: =BA24+AZ25 -> -208100.84 | ... BD25: =BD24+BC25 -> -265853.09 | BE25: =SUM(BE22:BE23) -> -265853.09
B26: Inversiones
B27: Act. Ganadera | C27: =-SUM('Ing y gtos'!AE131:AE136) -> 0 | D27: =-SUM('Ing y gtos'!AF131:AF136) -> 0 | E27: =-SUM('Ing y gtos'!AG131:AG136) -> 0 | F27: =-SUM('Ing y gtos'!AH131:AH136) -> 0 | G27: =-SUM('Ing y gtos'!AI131:AI136) -> -544.5 | H27: =-SUM('Ing y gtos'!AJ131:AJ136) -> -10393.93 | I27: =-SUM('Ing y gtos'!AK131:AK136) -> 0 | J27: =-SUM('Ing y gtos'!AL131:AL136) -> -1739.155 | ... N27: =-SUM('Ing y gtos'!AP131:AP136) -> 0 | O27: =SUM(C27:N27) -> -16790.485 | P27: =-SUM('Ing y gtos'!AU131:AU136) -> 0 | Q27: =-SUM('Ing y gtos'!AV131:AV136) -> 0 | R27: =-SUM('Ing y gtos'!AW131:AW136) -> 2750 | S27: =-SUM('Ing y gtos'!AX131:AX136) -> 0 | T27: =-SUM('Ing y gtos'!AY131:AY136) -> 375.5 | U27: =-SUM('Ing y gtos'!AZ131:AZ136) -> 1620 | V27: =-SUM('Ing y gtos'!BA131:BA136) -> 0 | W27: =-SUM('Ing y gtos'!BB131:BB136) -> 0 | ... AA27: =-SUM('Ing y gtos'!BF131:BF136) -> 0 | AB27: =SUM(P27:AA27) -> 3677.02 | AC27: =-SUM('Ing y gtos'!BJ131:BJ136) -> 0 | AD27: =-SUM('Ing y gtos'!BK131:BK136) -> 2475 | AE27: =-SUM('Ing y gtos'!BL131:BL136) -> 0 | AF27: =-SUM('Ing y gtos'!BM131:BM136) -> 0 | AG27: =-SUM('Ing y gtos'!BN131:BN136) -> 0 | AH27: =-SUM('Ing y gtos'!BO131:BO136) -> 0 | AI27: =-SUM('Ing y gtos'!BP131:BP136) -> 0 | AJ27: =-SUM('Ing y gtos'!BQ131:BQ136) -> 0 | ... AN27: =-SUM('Ing y gtos'!BU131:BU136) -> 0 | AO27: =SUM(AC27:AN27) -> 2475 | AS27: =-SUM('Ing y gtos'!BY131:BY136) -> 0 | AT27: =-SUM('Ing y gtos'!BZ131:BZ136) -> 0 | AU27: =-SUM('Ing y gtos'!CA131:CA136) -> 0 | AV27: =-SUM('Ing y gtos'!CB131:CB136) -> 0 | AW27: =-SUM('Ing y gtos'!CC131:CC136) -> 0 | AX27: =-SUM('Ing y gtos'!CD131:CD136) -> 0 | AY27: =-SUM('Ing y gtos'!CE131:CE136) -> 0 | AZ27: =-SUM('Ing y gtos'!CF131:CF136) -> 0 | ... BD27: =-SUM('Ing y gtos'!CJ131:CJ136) -> 0 | BE27: =SUM(AS27:BD27) -> 0
B29: Caja Inversiones (mes) | C29: =C27 -> 0 | D29: =D27 -> 0 | E29: =E27 -> 0 | F29: =F27 -> 0 | G29: =G27 -> -544.5 | H29: =H27 -> -10393.93 | I29: =I27 -> 0 | J29: =J27 -> -1739.155 | ... N29: =N27 -> 0 | P29: =P27 -> 0 | Q29: =Q27 -> 0 | R29: =R27 -> 2750 | S29: =S27 -> 0 | T29: =T27 -> 375.5 | U29: =U27 -> 1620 | V29: =V27 -> 0 | W29: =W27 -> 0 | ... AA29: =AA27 -> 0 | AC29: =AC27 -> 0 | AD29: =AD27 -> 2475 | AE29: =AE27 -> 0 | AF29: =AF27 -> 0 | AG29: =AG27 -> 0 | AH29: =AH27 -> 0 | AI29: =AI27 -> 0 | AJ29: =AJ27 -> 0 | ... AN29: =AN27 -> 0 | AS29: =AS27 -> 0 | AT29: =AT27 -> 0 | AU29: =AU27 -> 0 | AV29: =AV27 -> 0 | AW29: =AW27 -> 0 | AX29: =AX27 -> 0 | AY29: =AY27 -> 0 | AZ29: =AZ27 -> 0 | ... BD29: =BD27 -> 0
B30: Caja Inversiones (acum.) | C30: =C29 -> 0 | D30: =D29+C30 -> 0 | E30: =E29+D30 -> 0 | F30: =F29+E30 -> 0 | G30: =G29+F30 -> -544.5 | H30: =H29+G30 -> -10938.43 | I30: =I29+H30 -> -10938.43 | J30: =J29+I30 -> -12677.585 | K30: =K29+J30 -> -16790.485 | ... N30: =N29+M30 -> -16790.485 | O30: =SUM(O27:O28) -> -16790.485 | P30: =N27 -> 0 | Q30: =Q29+P30 -> 0 | R30: =R29+Q30 -> 2750 | S30: =S29+R30 -> 2750 | T30: =T29+S30 -> 3125.5 | U30: =U29+T30 -> 4745.5 | V30: =V29+U30 -> 4745.5 | W30: =W29+V30 -> 4745.5 | X30: =X29+W30 -> 1077.02 | ... AA30: =AA29+Z30 -> 3677.02 | AB30: =SUM(AB27:AB28) -> 3677.02 | AC30: =AA27 -> 0 | AD30: =AD29+AC30 -> 2475 | AE30: =AE29+AD30 -> 2475 | AF30: =AF29+AE30 -> 2475 | AG30: =AG29+AF30 -> 2475 | AH30: =AH29+AG30 -> 2475 | AI30: =AI29+AH30 -> 2475 | AJ30: =AJ29+AI30 -> 2475 | AK30: =AK29+AJ30 -> 2475 | ... AN30: =AN29+AM30 -> 2475 | AO30: =SUM(AO27:AO28) -> 2475 | AS30: =AQ27 -> 0 | AT30: =AT29+AS30 -> 0 | AU30: =AU29+AT30 -> 0 | AV30: =AV29+AU30 -> 0 | AW30: =AW29+AV30 -> 0 | AX30: =AX29+AW30 -> 0 | AY30: =AY29+AX30 -> 0 | AZ30: =AZ29+AY30 -> 0 | BA30: =BA29+AZ30 -> 0 | ... BD30: =BD29+BC30 -> 0 | BE30: =SUM(BE27:BE28) -> 0
B31: Financiación | C31: ='Ing y gtos'!AE147+'Ing y gtos'!AE150+'Ing y gtos'!AE153 -> 5000 | D31: ='Ing y gtos'!AF147+'Ing y gtos'!AF150+'Ing y gtos'!AF153 -> 9000 | E31: ='Ing y gtos'!AG147+'Ing y gtos'!AG150+'Ing y gtos'!AG153 -> 0 | F31: ='Ing y gtos'!AH147+'Ing y gtos'!AH150+'Ing y gtos'!AH153 -> 0 | G31: ='Ing y gtos'!AI147+'Ing y gtos'!AI150+'Ing y gtos'!AI153 -> 0 | H31: ='Ing y gtos'!AJ147+'Ing y gtos'!AJ150+'Ing y gtos'!AJ153 -> 0 | I31: ='Ing y gtos'!AK147+'Ing y gtos'!AK150+'Ing y gtos'!AK153 -> 0 | J31: ='Ing y gtos'!AL147+'Ing y gtos'!AL150+'Ing y gtos'!AL153 -> 0 | ... N31: ='Ing y gtos'!AP147+'Ing y gtos'!AP150+'Ing y gtos'!AP153 -> 0 | O31: =SUM(C31:N31) -> 14000 | P31: ='Ing y gtos'!AU147+'Ing y gtos'!AU150+'Ing y gtos'!AU153 -> 0 | Q31: ='Ing y gtos'!AV147+'Ing y gtos'!AV150+'Ing y gtos'!AV153 -> 0 | R31: ='Ing y gtos'!AW147+'Ing y gtos'!AW150+'Ing y gtos'!AW153 -> 10000 | S31: ='Ing y gtos'!AX147+'Ing y gtos'!AX150+'Ing y gtos'!AX153 -> 21000 | T31: ='Ing y gtos'!AY147+'Ing y gtos'!AY150+'Ing y gtos'!AY153 -> 15000 | U31: ='Ing y gtos'!AZ147+'Ing y gtos'!AZ150+'Ing y gtos'!AZ153 -> 13500 | V31: ='Ing y gtos'!BA147+'Ing y gtos'!BA150+'Ing y gtos'!BA153 -> 0 | W31: ='Ing y gtos'!BB147+'Ing y gtos'!BB150+'Ing y gtos'!BB153 -> -10000 | X31: ='Ing y gtos'!BC147+'Ing y gtos'!BC150+'Ing y gtos'!BC153 -> -15000 | Y31: ='Ing y gtos'!BD141+'Ing y gtos'!BD147+'Ing y gtos'!BD150+'Ing y gtos'!BD153 -> 915 | Z31: ='Ing y gtos'!BE141+'Ing y gtos'!BE147+'Ing y gtos'!BE150+'Ing y gtos'!BE153 -> 0 | AA31: ='Ing y gtos'!BF141+'Ing y gtos'!BF147+'Ing y gtos'!BF150+'Ing y gtos'!BF153 -> 12000 | AB31: =SUM(P31:AA31) -> 47415 | AC31: ='Ing y gtos'!BJ141+'Ing y gtos'!BJ147+'Ing y gtos'!BJ150+'Ing y gtos'!BJ153 -> 5350 | AD31: ='Ing y gtos'!BK141+'Ing y gtos'!BK147+'Ing y gtos'!BK150+'Ing y gtos'!BK153 -> 33000 | AE31: ='Ing y gtos'!BL141+'Ing y gtos'!BL147+'Ing y gtos'!BL150+'Ing y gtos'!BL153 -> 250 | AF31: ='Ing y gtos'!BM141+'Ing y gtos'!BM147+'Ing y gtos'!BM150+'Ing y gtos'!BM153 -> 595 | AG31: ='Ing y gtos'!BN141+'Ing y gtos'!BN147+'Ing y gtos'!BN150+'Ing y gtos'!BN153 -> 12000 | AH31: ='Ing y gtos'!BO141+'Ing y gtos'!BO147+'Ing y gtos'!BO150+'Ing y gtos'!BO153 -> 5000 | AI31: ='Ing y gtos'!BP141+'Ing y gtos'!BP147+'Ing y gtos'!BP150+'Ing y gtos'!BP153 -> 12150 | AJ31: ='Ing y gtos'!BQ141+'Ing y gtos'!BQ147+'Ing y gtos'!BQ150+'Ing y gtos'!BQ153 -> -21405 | ... AN31: ='Ing y gtos'!BU141+'Ing y gtos'!BU147+'Ing y gtos'!BU150+'Ing y gtos'!BU153 -> 0 | AO31: =SUM(AC31:AN31) -> 49085 | AS31: ='Ing y gtos'!BY147+'Ing y gtos'!BY150+'Ing y gtos'!BY153 -> 20000 | AT31: ='Ing y gtos'!BZ147+'Ing y gtos'!BZ150+'Ing y gtos'!BZ153 -> 0 | AU31: ='Ing y gtos'!CA147+'Ing y gtos'!CA150+'Ing y gtos'!CA153 -> 0 | AV31: ='Ing y gtos'!CB147+'Ing y gtos'!CB150+'Ing y gtos'!CB153 -> 0 | AW31: ='Ing y gtos'!CC147+'Ing y gtos'!CC150+'Ing y gtos'!CC153 -> 25000 | AX31: ='Ing y gtos'!CD147+'Ing y gtos'!CD150+'Ing y gtos'!CD153 -> 0 | AY31: ='Ing y gtos'!CE147+'Ing y gtos'!CE150+'Ing y gtos'!CE153 -> -25000 | AZ31: ='Ing y gtos'!CF147+'Ing y gtos'!CF150+'Ing y gtos'!CF153 -> 0 | ... BD31: ='Ing y gtos'!CJ147+'Ing y gtos'!CJ150+'Ing y gtos'!CJ153 -> 0 | BE31: =SUM(AS31:BD31) -> -57000
B33: Caja Financiación (mes) | C33: =C31 -> 5000 | D33: =D31 -> 9000 | E33: =E31 -> 0 | F33: =F31 -> 0 | G33: =G31 -> 0 | H33: =H31 -> 0 | I33: =I31 -> 0 | J33: =J31 -> 0 | ... N33: =N31 -> 0 | P33: =P31 -> 0 | Q33: =Q31 -> 0 | R33: =R31 -> 10000 | S33: =S31 -> 21000 | T33: =T31 -> 15000 | U33: =U31 -> 13500 | V33: =V31 -> 0 | W33: =W31 -> -10000 | ... AA33: =AA31 -> 12000 | AC33: =AC31 -> 5350 | AD33: =AD31 -> 33000 | AE33: =AE31 -> 250 | AF33: =AF31 -> 595 | AG33: =AG31 -> 12000 | AH33: =AH31 -> 5000 | AI33: =AI31 -> 12150 | AJ33: =AJ31 -> -21405 | ... AN33: =AN31 -> 0 | AS33: =AS31 -> 20000 | AT33: =AT31 -> 0 | AU33: =AU31 -> 0 | AV33: =AV31 -> 0 | AW33: =AW31 -> 25000 | AX33: =AX31 -> 0 | AY33: =AY31 -> -25000 | AZ33: =AZ31 -> 0 | ... BD33: =BD31 -> 0
B34: Caja Financiación (acum.) | C34: =C33 -> 5000 | D34: =D33+C34 -> 14000 | E34: =E33+D34 -> 14000 | F34: =F33+E34 -> 14000 | G34: =G33+F34 -> 14000 | H34: =H33+G34 -> 14000 | I34: =I33+H34 -> 14000 | J34: =J33+I34 -> 14000 | K34: =K33+J34 -> 14000 | ... N34: =N33+M34 -> 14000 | O34: =SUM(O31:O32) -> 14000 | P34: =P33 -> 0 | Q34: =Q33+P34 -> 0 | R34: =R33+Q34 -> 10000 | S34: =S33+R34 -> 31000 | T34: =T33+S34 -> 46000 | U34: =U33+T34 -> 59500 | V34: =V33+U34 -> 59500 | W34: =W33+V34 -> 49500 | X34: =X33+W34 -> 34500 | ... AA34: =AA33+Z34 -> 47415 | AB34: =SUM(AB31:AB32) -> 47415 | AC34: =AC33 -> 5350 | AD34: =AD33+AC34 -> 38350 | AE34: =AE33+AD34 -> 38600 | AF34: =AF33+AE34 -> 39195 | AG34: =AG33+AF34 -> 51195 | AH34: =AH33+AG34 -> 56195 | AI34: =AI33+AH34 -> 68345 | AJ34: =AJ33+AI34 -> 46940 | AK34: =AK33+AJ34 -> 48940 | ... AN34: =AN33+AM34 -> 49085 | AO34: =SUM(AO31:AO32) -> 49085 | AS34: =AS33 -> 20000 | AT34: =AT33+AS34 -> 20000 | AU34: =AU33+AT34 -> 20000 | AV34: =AV33+AU34 -> 20000 | AW34: =AW33+AV34 -> 45000 | AX34: =AX33+AW34 -> 45000 | AY34: =AY33+AX34 -> 20000 | AZ34: =AZ33+AY34 -> 20000 | BA34: =BA33+AZ34 -> -2000 | ... BD34: =BD33+BC34 -> -57000 | BE34: =SUM(BE31:BE32) -> -57000
B36: Caja opex, capex y serv. deuda | C36: =C7+C13+C19+C24+C29+C33 -> 260.89 | D36: =D7+D13+D19+D24+D29+D33 -> 27680.86 | E36: =E7+E13+E19+E24+E29+E33 -> 53816.9 | F36: =F7+F13+F19+F24+F29+F33 -> -48641.77 | G36: =G7+G13+G19+G24+G29+G33 -> 4706.6782 | H36: =H7+H13+H19+H24+H29+H33 -> -20153.35 | I36: =I7+I13+I19+I24+I29+I33 -> -8615.5879 | J36: =J7+J13+J19+J24+J29+J33 -> 38110.455 | ... N36: =N7+N13+N19+N24+N29+N33 -> -69953.2 | O36: =SUM(O8,O14,O20,O25,O30,O34) -> 17549.165 | P36: =P7+P13+P19+P24+P29+P33 -> 12687.52 | Q36: =Q7+Q13+Q19+Q24+Q29+Q33 -> 7311.85 | R36: =R7+R13+R19+R24+R29+R33 -> -29513.33 | S36: =S7+S13+S19+S24+S29+S33 -> 6259.84 | T36: =T7+T13+T19+T24+T29+T33 -> -6502.44 | U36: =U7+U13+U19+U24+U29+U33 -> 18087.01 | V36: =V7+V13+V19+V24+V29+V33 -> 8306.78 | W36: =W7+W13+W19+W24+W29+W33 -> 7121.89 | ... AA36: =AA7+AA13+AA19+AA24+AA29+AA33 -> 22068.58 | AB36: =SUM(AB8,AB14,AB20,AB25,AB30,AB34) -> 16078.82 | AC36: =AC7+AC13+AC19+AC24+AC29+AC33 -> -31889.87 | AD36: =AD7+AD13+AD19+AD24+AD29+AD33 -> 28634.12 | AE36: =AE7+AE13+AE19+AE24+AE29+AE33 -> -2648.52 | AF36: =AF7+AF13+AF19+AF24+AF29+AF33 -> -25532.65 | AG36: =AG7+AG13+AG19+AG24+AG29+AG33 -> -806.39 | AH36: =AH7+AH13+AH19+AH24+AH29+AH33 -> 14893.91 | AI36: =AI7+AI13+AI19+AI24+AI29+AI33 -> -10395.91 | AJ36: =AJ7+AJ13+AJ19+AJ24+AJ29+AJ33 -> 22131.8 | ... AN36: =AN7+AN13+AN19+AN24+AN29+AN33 -> 19155.16 | AO36: =SUM(AO8,AO14,AO20,AO25,AO30,AO34) -> -7446.24 | AS36: =AS7+AS13+AS19+AS24+AS29+AS33 -> -24051.27 | AT36: =AT7+AT13+AT19+AT24+AT29+AT33 -> 10751.2 | AU36: =AU7+AU13+AU19+AU24+AU29+AU33 -> -5000.79 | AV36: =AV7+AV13+AV19+AV24+AV29+AV33 -> -3505.97 | AW36: =AW7+AW13+AW19+AW24+AW29+AW33 -> 7493.12 | AX36: =AX7+AX13+AX19+AX24+AX29+AX33 -> 24655.05 | AY36: =AY7+AY13+AY19+AY24+AY29+AY33 -> 28536.16 | AZ36: =AZ7+AZ13+AZ19+AZ24+AZ29+AZ33 -> 16358.93 | ... BD36: =BD7+BD13+BD19+BD24+BD29+BD33 -> 14744.51 | BE36: =SUM(BE8,BE14,BE20,BE25,BE30,BE34) -> 878.62
B37: Check | O37: =SUM(C36:N36)-O36 -> 0 | AB37: =SUM(P36:AA36)-AB36 -> 1.6370905e-11 | AO37: =SUM(AC36:AN36)-AO36 -> 4.3655746e-11 | BE37: =SUM(AS36:BD36)-BE36 -> 4.3655746e-11
B38: Total circulante
B40: Caja consolidada (mes) | C40: =C7+C13+C19+C24+C29+C33 -> 260.89 | D40: =D7+D13+D19+D24+D29+D33 -> 27680.86 | E40: =E7+E13+E19+E24+E29+E33 -> 53816.9 | F40: =F7+F13+F19+F24+F29+F33 -> -48641.77 | G40: =G7+G13+G19+G24+G29+G33 -> 4706.6782 | H40: =H7+H13+H19+H24+H29+H33 -> -20153.35 | I40: =I7+I13+I19+I24+I29+I33 -> -8615.5879 | J40: =J7+J13+J19+J24+J29+J33 -> 38110.455 | ... N40: =N7+N13+N19+N24+N29+N33 -> -69953.2 | P40: =P7+P13+P19+P24+P29+P33 -> 12687.52 | Q40: =Q7+Q13+Q19+Q24+Q29+Q33 -> 7311.85 | R40: =R7+R13+R19+R24+R29+R33 -> -29513.33 | S40: =S7+S13+S19+S24+S29+S33 -> 6259.84 | T40: =T7+T13+T19+T24+T29+T33 -> -6502.44 | U40: =U7+U13+U19+U24+U29+U33 -> 18087.01 | V40: =V7+V13+V19+V24+V29+V33 -> 8306.78 | W40: =W7+W13+W19+W24+W29+W33 -> 7121.89 | ... AA40: =AA7+AA13+AA19+AA24+AA29+AA33 -> 22068.58 | AC40: =AC7+AC13+AC19+AC24+AC29+AC33 -> -31889.87 | AD40: =AD7+AD13+AD19+AD24+AD29+AD33 -> 28634.12 | AE40: =AE7+AE13+AE19+AE24+AE29+AE33 -> -2648.52 | AF40: =AF7+AF13+AF19+AF24+AF29+AF33 -> -25532.65 | AG40: =AG7+AG13+AG19+AG24+AG29+AG33 -> -806.39 | AH40: =AH7+AH13+AH19+AH24+AH29+AH33 -> 14893.91 | AI40: =AI7+AI13+AI19+AI24+AI29+AI33 -> -10395.91 | AJ40: =AJ7+AJ13+AJ19+AJ24+AJ29+AJ33 -> 22131.8 | ... AN40: =AN7+AN13+AN19+AN24+AN29+AN33 -> 19155.16 | AS40: =AS7+AS13+AS19+AS24+AS29+AS33 -> -24051.27 | AT40: =AT7+AT13+AT19+AT24+AT29+AT33 -> 10751.2 | AU40: =AU7+AU13+AU19+AU24+AU29+AU33 -> -5000.79 | AV40: =AV7+AV13+AV19+AV24+AV29+AV33 -> -3505.97 | AW40: =AW7+AW13+AW19+AW24+AW29+AW33 -> 7493.12 | AX40: =AX7+AX13+AX19+AX24+AX29+AX33 -> 24655.05 | AY40: =AY7+AY13+AY19+AY24+AY29+AY33 -> 28536.16 | AZ40: =AZ7+AZ13+AZ19+AZ24+AZ29+AZ33 -> 16358.93 | ... BD40: =BD7+BD13+BD19+BD24+BD29+BD33 -> 14744.51
B41: Caja consolidada (acumulada) | C41: =C40 -> 260.89 | D41: =D40+C41 -> 27941.75 | E41: =E40+D41 -> 81758.65 | F41: =F40+E41 -> 33116.88 | G41: =G40+F41 -> 37823.558 | H41: =H40+G41 -> 17670.208 | I41: =I40+H41 -> 9054.6203 | J41: =J40+I41 -> 47165.075 | K41: =K40+J41 -> 102302.39 | ... N41: =N40+M41 -> 17549.165 | P41: =P40 -> 12687.52 | Q41: =Q40+P41 -> 19999.37 | R41: =R40+Q41 -> -9513.96 | S41: =S40+R41 -> -3254.12 | T41: =T40+S41 -> -9756.56 | U41: =U40+T41 -> 8330.45 | V41: =V40+U41 -> 16637.23 | W41: =W40+V41 -> 23759.12 | X41: =X40+W41 -> 9604.23 | ... AA41: =AA40+Z41 -> 16078.82 | AC41: =AC40 -> -31889.87 | AD41: =AD40+AC41 -> -3255.75 | AE41: =AE40+AD41 -> -5904.27 | AF41: =AF40+AE41 -> -31436.92 | AG41: =AG40+AF41 -> -32243.31 | AH41: =AH40+AG41 -> -17349.4 | AI41: =AI40+AH41 -> -27745.31 | AJ41: =AJ40+AI41 -> -5613.51 | AK41: =AK40+AJ41 -> -33165.8 | ... AN41: =AN40+AM41 -> -7446.24 | AS41: =AS40 -> -24051.27 | AT41: =AT40+AS41 -> -13300.07 | AU41: =AU40+AT41 -> -18300.86 | AV41: =AV40+AU41 -> -21806.83 | AW41: =AW40+AV41 -> -14313.71 | AX41: =AX40+AW41 -> 10341.34 | AY41: =AY40+AX41 -> 38877.5 | AZ41: =AZ40+AY41 -> 55236.43 | BA41: =BA40+AZ41 -> 32284.1 | ... BD41: =BD40+BC41 -> 878.62
B43: Saldo Inicial | C43: ='Ing y gtos'!$AA$157 -> 1178.6 | D43: =C45 -> 1439.49 | E43: =D45 -> 29120.35 | F43: =E45 -> 82937.25 | G43: =F45 -> 34295.48 | H43: =G45 -> 39002.158 | I43: =H45 -> 18848.808 | J43: =I45 -> 10233.22 | K43: =J45 -> 48343.675 | ... N43: =M45 -> 88680.965 | P43: =N45 -> 18727.765 | Q43: =P45 -> 31415.285 | R43: =Q45 -> 38727.135 | S43: =R45 -> 9213.8053 | T43: =S45 -> 15473.645 | U43: =T45 -> 8971.2053 | V43: =U45 -> 27058.215 | W43: =V45 -> 35364.995 | X43: =W45 -> 42486.885 | ... AA43: =Z45 -> 12738.005 | AC43: =AA45 -> 34806.585 | AD43: =AC45 -> 2916.7153 | AE43: =AD45 -> 31550.835 | AF43: =AE45 -> 28902.315 | AG43: =AF45 -> 3369.6653 | AH43: =AG45 -> 2563.2753 | AI43: =AH45 -> 17457.185 | AJ43: =AI45 -> 7061.2753 | AK43: =AJ45 -> 29193.075 | ... AN43: =AM45 -> 8205.1853 | AS43: =AN45 -> 27360.345 | AT43: =AS45 -> 3309.0753 | AU43: =AT45 -> 14060.275 | AV43: =AU45 -> 9059.4853 | AW43: =AV45 -> 5553.5153 | AX43: =AW45 -> 13046.635 | AY43: =AX45 -> 37701.685 | AZ43: =AY45 -> 66237.845 | BA43: =AZ45 -> 82596.775 | ... BD43: =BC45 -> 13494.455
B44: Caja consolidada | C44: =C40 -> 260.89 | D44: =D40 -> 27680.86 | E44: =E40 -> 53816.9 | F44: =F40 -> -48641.77 | G44: =G40 -> 4706.6782 | H44: =H40 -> -20153.35 | I44: =I40 -> -8615.5879 | J44: =J40 -> 38110.455 | ... N44: =N40 -> -69953.2 | P44: =P40 -> 12687.52 | Q44: =Q40 -> 7311.85 | R44: =R40 -> -29513.33 | S44: =S40 -> 6259.84 | T44: =T40 -> -6502.44 | U44: =U40 -> 18087.01 | V44: =V40 -> 8306.78 | W44: =W40 -> 7121.89 | ... AA44: =AA40 -> 22068.58 | AC44: =AC40 -> -31889.87 | AD44: =AD40 -> 28634.12 | AE44: =AE40 -> -2648.52 | AF44: =AF40 -> -25532.65 | AG44: =AG40 -> -806.39 | AH44: =AH40 -> 14893.91 | AI44: =AI40 -> -10395.91 | AJ44: =AJ40 -> 22131.8 | ... AN44: =AN40 -> 19155.16 | AS44: =AS40 -> -24051.27 | AT44: =AT40 -> 10751.2 | AU44: =AU40 -> -5000.79 | AV44: =AV40 -> -3505.97 | AW44: =AW40 -> 7493.12 | AX44: =AX40 -> 24655.05 | AY44: =AY40 -> 28536.16 | AZ44: =AZ40 -> 16358.93 | ... BD44: =BD40 -> 14744.51
B45: Saldo final | C45: =SUM(C43:C44) -> 1439.49 | D45: =SUM(D43:D44) -> 29120.35 | E45: =SUM(E43:E44) -> 82937.25 | F45: =SUM(F43:F44) -> 34295.48 | G45: =SUM(G43:G44) -> 39002.158 | H45: =SUM(H43:H44) -> 18848.808 | I45: =SUM(I43:I44) -> 10233.22 | J45: =SUM(J43:J44) -> 48343.675 | ... N45: =SUM(N43:N44) -> 18727.765 | P45: =SUM(P43:P44) -> 31415.285 | Q45: =SUM(Q43:Q44) -> 38727.135 | R45: =SUM(R43:R44) -> 9213.8053 | S45: =SUM(S43:S44) -> 15473.645 | T45: =SUM(T43:T44) -> 8971.2053 | U45: =SUM(U43:U44) -> 27058.215 | V45: =SUM(V43:V44) -> 35364.995 | W45: =SUM(W43:W44) -> 42486.885 | ... AA45: =SUM(AA43:AA44) -> 34806.585 | AC45: =SUM(AC43:AC44) -> 2916.7153 | AD45: =SUM(AD43:AD44) -> 31550.835 | AE45: =SUM(AE43:AE44) -> 28902.315 | AF45: =SUM(AF43:AF44) -> 3369.6653 | AG45: =SUM(AG43:AG44) -> 2563.2753 | AH45: =SUM(AH43:AH44) -> 17457.185 | AI45: =SUM(AI43:AI44) -> 7061.2753 | AJ45: =SUM(AJ43:AJ44) -> 29193.075 | ... AN45: =SUM(AN43:AN44) -> 27360.345 | AS45: =SUM(AS43:AS44) -> 3309.0753 | AT45: =SUM(AT43:AT44) -> 14060.275 | AU45: =SUM(AU43:AU44) -> 9059.4853 | AV45: =SUM(AV43:AV44) -> 5553.5153 | AW45: =SUM(AW43:AW44) -> 13046.635 | AX45: =SUM(AX43:AX44) -> 37701.685 | AY45: =SUM(AY43:AY44) -> 66237.845 | AZ45: =SUM(AZ43:AZ44) -> 82596.775 | ... BD45: =SUM(BD43:BD44) -> 28238.965
B46: Saldos bancarios
B47: Saldo Caixa EUR | C47: ='Ing y gtos'!AE159 -> 1449.16 | D47: ='Ing y gtos'!AF159 -> 29148.21 | E47: ='Ing y gtos'!AG159 -> 82883.58 | F47: ='Ing y gtos'!AH159 -> 34241.81 | G47: ='Ing y gtos'!AI159 -> 36138.49 | H47: ='Ing y gtos'!AJ159 -> 16786.84 | I47: ='Ing y gtos'!AK159 -> 8792.55 | J47: ='Ing y gtos'!AL159 -> 47903.01 | ... N47: ='Ing y gtos'!AP159 -> 18021.45 | P47: ='Ing y gtos'!AU158 -> 921 | Q47: ='Ing y gtos'!AV158 -> 14978.31 | R47: ='Ing y gtos'!AW158 -> 957.31 | S47: ='Ing y gtos'!AX158 -> 2913.34 | T47: ='Ing y gtos'!AY158 -> 199.29 | U47: ='Ing y gtos'!AZ158 -> 79.29 | V47: ='Ing y gtos'!BA158 -> 39.29 | W47: ='Ing y gtos'!BB158 -> 1347.93 | ... AA47: ='Ing y gtos'!BF158 -> 166.96 | AC47: ='Ing y gtos'!BJ158 -> 126.96 | AD47: ='Ing y gtos'!BK158 -> 18595.53 | AE47: ='Ing y gtos'!BL158 -> 17889.95 | AF47: ='Ing y gtos'!BM158 -> 215.55 | AG47: ='Ing y gtos'!BN158 -> 205.55 | AH47: ='Ing y gtos'!BO158 -> 205.55 | AI47: ='Ing y gtos'!BP158 -> 40.56 | AJ47: ='Ing y gtos'!BQ158 -> 40.56 | ... AN47: ='Ing y gtos'!BU158 -> 0 | AS47: ='Ing y gtos'!BW158 -> 0 | AT47: ='Ing y gtos'!#REF! -> #REF! | AU47: ='Ing y gtos'!BX158 -> 0 | AV47: ='Ing y gtos'!BY158 -> 0 | AW47: ='Ing y gtos'!BZ158 -> 0 | AX47: ='Ing y gtos'!CA158 -> 0 | AY47: ='Ing y gtos'!CB158 -> 0 | AZ47: ='Ing y gtos'!CC158 -> 0 | BA47: ='Ing y gtos'!CD158 -> 0 | BB47: ='Ing y gtos'!CE158 -> 0 | ... BD47: ='Ing y gtos'!CG158 -> 0
B48: Saldo Caja Rural | C48: ='Ing y gtos'!AE158 -> -9.67 | D48: ='Ing y gtos'!AF158 -> -27.86 | E48: ='Ing y gtos'!AG158 -> 53.67 | F48: ='Ing y gtos'!AH158 -> 53.67 | G48: ='Ing y gtos'!AI158 -> 53.67 | H48: ='Ing y gtos'!AJ158 -> 51.97 | I48: ='Ing y gtos'!AK158 -> 105.67 | J48: ='Ing y gtos'!AL158 -> 105.67 | ... N48: ='Ing y gtos'!AP158 -> 401.32 | P48: ='Ing y gtos'!AU159 -> 29979.29 | Q48: ='Ing y gtos'!AV159 -> 23100.83 | R48: ='Ing y gtos'!AW159 -> 8218.5 | S48: ='Ing y gtos'!AX159 -> 12522.31 | T48: ='Ing y gtos'!AY159 -> 6795.92 | U48: ='Ing y gtos'!AZ159 -> 23832.93 | V48: ='Ing y gtos'!BA159 -> 32169.71 | W48: ='Ing y gtos'!BB159 -> 37982.96 | ... AA48: ='Ing y gtos'!BF159 -> 34559.63 | AC48: ='Ing y gtos'!BJ159 -> 2789.76 | AD48: ='Ing y gtos'!BK159 -> 12955.31 | AE48: ='Ing y gtos'!BL159 -> 11012.37 | AF48: ='Ing y gtos'!BM159 -> 3154.12 | AG48: ='Ing y gtos'!BN159 -> 2357.73 | AH48: ='Ing y gtos'!BO159 -> 16681.64 | AI48: ='Ing y gtos'!BP159 -> 7020.72 | AJ48: ='Ing y gtos'!BQ159 -> 29152.51 | ... AN48: ='Ing y gtos'!BU159 -> 0 | AS48: ='Ing y gtos'!BW159 -> 0 | AT48: ='Ing y gtos'!#REF! -> #REF! | AU48: ='Ing y gtos'!BX159 -> 0 | AV48: ='Ing y gtos'!BY159 -> 0 | AW48: ='Ing y gtos'!BZ159 -> 0 | AX48: ='Ing y gtos'!CA159 -> 0 | AY48: ='Ing y gtos'!CB159 -> 0 | AZ48: ='Ing y gtos'!CC159 -> 0 | BA48: ='Ing y gtos'!CD159 -> 0 | BB48: ='Ing y gtos'!CE159 -> 0 | ... BD48: ='Ing y gtos'!CG159 -> 0
B49: Saldo Caja | C49: ='Ing y gtos'!AE160 -> 0 | D49: ='Ing y gtos'!AF160 -> 0 | E49: ='Ing y gtos'!AG160 -> 0 | F49: ='Ing y gtos'!AH160 -> 0 | G49: ='Ing y gtos'!AI160 -> 2810 | H49: ='Ing y gtos'!AJ160 -> 2010 | I49: ='Ing y gtos'!AK160 -> 1335 | J49: ='Ing y gtos'!AL160 -> 335 | ... N49: ='Ing y gtos'!AP160 -> 305 | P49: ='Ing y gtos'!AU160 -> 515 | Q49: ='Ing y gtos'!AV160 -> 648 | R49: ='Ing y gtos'!AW160 -> 38 | S49: ='Ing y gtos'!AX160 -> 38 | T49: ='Ing y gtos'!AY160 -> 1976 | U49: ='Ing y gtos'!AZ160 -> 3146 | V49: ='Ing y gtos'!BA160 -> 3156 | W49: ='Ing y gtos'!BB160 -> 3156 | ... AA49: ='Ing y gtos'!BF160 -> 80 | AC49: ='Ing y gtos'!BJ160 -> 0 | AD49: ='Ing y gtos'!BK160 -> 0 | AE49: ='Ing y gtos'!BL160 -> 0 | AF49: ='Ing y gtos'!BM160 -> 0 | AG49: ='Ing y gtos'!BN160 -> 0 | AH49: ='Ing y gtos'!BO160 -> 570 | AI49: ='Ing y gtos'!BP160 -> 0 | AJ49: ='Ing y gtos'!BQ160 -> 0 | ... AN49: ='Ing y gtos'!BU160 -> 0 | AS49: ='Ing y gtos'!BW160 -> 0 | AT49: ='Ing y gtos'!#REF! -> #REF! | AU49: ='Ing y gtos'!BX160 -> 0 | AV49: ='Ing y gtos'!BY160 -> 0 | AW49: ='Ing y gtos'!BZ160 -> 0 | AX49: ='Ing y gtos'!CA160 -> 0 | AY49: ='Ing y gtos'!CB160 -> 0 | AZ49: ='Ing y gtos'!CC160 -> 0 | BA49: ='Ing y gtos'!CD160 -> 0 | BB49: ='Ing y gtos'!CE160 -> 0 | ... BD49: ='Ing y gtos'!CG160 -> 0
...

Sheet Comparativa cuadros
N1: 23-24 | O1: 24-25 | P1: 26-26
B2: PRESUPUESTO 25-26 | N2: Totales | O2: TOTALES
A3: Ventas vacuno | B3: 46162 | M3: Ventas vacuno
A4: Venta de terneros/as | B4: 113346.91 | D4: ='Ing y gtos'!BV4 -> 113346.91 | E4: =D4-B4 -> 0 | F4: aumento de 2 terneros de venta intermedio y 1 mas de remate. | M4: Venta de terneros/as | N4: 167719.55 | O4: 73996.36 | P4: ='Ing y gtos'!BV4 -> 113346.91 | Q4: ¿Por qué disminuye del 23-24 al 24-25? 1º no hemos vendido tantos terneros y 2º el primero año vendidmos mas terneros engorde.
A5: Venta de carne | B5: 18260.02 | D5: ='Ing y gtos'!BV5 -> 18260.02 | E5: =D5-B5 -> 0 | F5: Facturas emitidas | M5: Venta de carne | N5: 13344.7 | O5: 8865.17 | P5: ='Ing y gtos'!BV5 -> 18260.02
A6: Total Ventas vacuno | B6: 131606.93 | D6: ='Ing y gtos'!BV6 -> 131606.93 | E6: =D6-B6 -> 0 | F6: AUMENTA COBROS | M6: Total Ventas vacuno | N6: 181064.25 | O6: 82861.53 | P6: ='Ing y gtos'!BV6 -> 131606.93
A7: Check | B7: 0 | D7: ='Ing y gtos'!BV7 -> 0 | M7: Check | N7: 0 | O7: 0 | P7: ='Ing y gtos'!BV7 -> 0
A9: Subvención PAC ganaderos extensivos de vacuno de carne | B9: 11610.39 | D9: ='Ing y gtos'!BV9 -> 11610.39 | E9: =D9-B9 -> 0 | M9: Subvención PAC ganaderos extensivos de vacuno de carne | N9: 12767.42 | O9: 11139.77 | P9: ='Ing y gtos'!BV9 -> 11610.39
A10: Subvención PAC ganado ecológico | B10: 0 | D10: ='Ing y gtos'!BV10 -> 0 | E10: =D10-B10 -> 0 | M10: Subvención PAC ganado ecológico | N10: 0 | O10: 0 | P10: ='Ing y gtos'!BV10 -> 0
A11: Subvención PAC ayuda basica a la renta y pago redistributivo | B11: 18438.27 | D11: ='Ing y gtos'!BV11 -> 18438.27 | E11: =D11-B11 -> 0 | M11: Subvención PAC ayuda basica a la renta y pago redistributivo | N11: 8056.6 | O11: 18834.78 | P11: ='Ing y gtos'!BV11 -> 18438.27
A12: Subvención PAC pastoreo extensivo | B12: 7590.12 | D12: ='Ing y gtos'!BV12 -> 7590.12 | E12: =D12-B12 -> 0 | M12: Subvención PAC pastoreo extensivo | N12: 10973.02 | O12: 7847.64 | P12: ='Ing y gtos'!BV12 -> 7590.12
A13: Subvención medicamentos vacas | B13: 0 | D13: ='Ing y gtos'!BV13 -> 0 | E13: =D13-B13 -> 0 | M13: Subvención medicamentos vacas | N13: 0 | O13: 0 | P13: ='Ing y gtos'!BV13 -> 0
A14: Subvención agroseguro vacas | B14: 1711.8 | D14: ='Ing y gtos'!BV14 -> 1711.8 | E14: =D14-B14 -> 0 | M14: Subvención agroseguro vacas | N14: 5725.81 | O14: 0 | P14: ='Ing y gtos'!BV14 -> 1711.8
A15: Subvenciones extraordinarias | B15: 5337.45 | D15: ='Ing y gtos'!BV15 -> 5337.45 | E15: =D15-B15 -> 0 | M15: Total cobros vacuno | N15: 218587.1 | O15: 120683.72 | P15: ='Ing y gtos'!BV16 -> 176294.96
A16: Total cobros vacuno | B16: 176294.96 | D16: ='Ing y gtos'!BV16 -> 176294.96 | E16: =D16-B16 -> 0 | F16: AUMENTA COBROS | M16: Check | N16: 0 | O16: 0 | P16: ='Ing y gtos'!BV17 -> 0
A17: Check | B17: 0 | D17: ='Ing y gtos'!BV17 -> 0 | M17: Gastos vacuno
A18: Gastos vacuno | M18: Compra terneros | N18: 0 | O18: 0 | P18: ='Ing y gtos'!BV19 -> 0
A19: Compra terneros | B19: 0 | D19: ='Ing y gtos'!BV19 -> 0 | E19: =D19-B19 -> 0 | M19: Medicamentos, veterinario y saneamientos | N19: 8991.32 | O19: 10113.08 | P19: ='Ing y gtos'!BV20 -> 10361.79
A20: Medicamentos, veterinario y saneamientos | B20: 7845.52 | D20: ='Ing y gtos'!BV20 -> 10361.79 | E20: =D20-B20 -> 2516.27 | F20: Disminuye prevision gastos mayo | M20: Programa de gestión | N20: 921.0036 | O20: 1650.81 | P20: ='Ing y gtos'!BV21 -> 1046.89
A21: Programa de gestión | B21: 1046.89 | D21: ='Ing y gtos'!BV21 -> 1046.89 | E21: =D21-B21 -> 0 | M21: Registro Angus | N21: 0 | O21: 0 | P21: ='Ing y gtos'!BV22 -> 350
A22: Registro Angus | B22: 350 | D22: ='Ing y gtos'!BV22 -> 350 | E22: =D22-B22 -> 0 | M22: Animales muertos | N22: 0 | O22: 883.96 | P22: ='Ing y gtos'!BV23 -> 1257.5
A23: Animales muertos | B23: 1257.5 | D23: ='Ing y gtos'!BV23 -> 1257.5 | E23: =D23-B23 -> 0 | M23: Cert. Ecológico - Agrocolor | N23: 1486.49 | O23: 1160.75 | P23: ='Ing y gtos'!BV24 -> 2560.58
A24: Cert. Ecológico - Agrocolor | B24: 2560.58 | D24: ='Ing y gtos'!BV24 -> 2560.58 | E24: =D24-B24 -> 0 | M24: Seguro Vacas | N24: 2557.09 | O24: -3912.61 | P24: ='Ing y gtos'!BV25 -> 3949.81
A25: Seguro Vacas | B25: 3949.81 | D25: ='Ing y gtos'!BV25 -> 3949.81 | E25: =D25-B25 -> 0 | M25: Matadero (Para venta de carne) | N25: 0 | O25: 0 | P25: ='Ing y gtos'!BV26 -> 0
A26: Matadero (Para venta de carne) | B26: 0 | D26: ='Ing y gtos'!BV26 -> 0 | E26: =D26-B26 -> 0 | M26: Portes (Para venta de carne) | N26: 0 | O26: 160.19 | P26: ='Ing y gtos'!BV27 -> 0
A27: Portes (Para venta de carne) | B27: 0 | D27: ='Ing y gtos'!BV27 -> 0 | E27: =D27-B27 -> 0 | M27: Envasado y refrigeración | N27: 0 | O27: 0 | P27: ='Ing y gtos'!BV28 -> 0
A28: Envasado y refrigeración | B28: 0 | D28: ='Ing y gtos'!BV28 -> 0 | E28: =D28-B28 -> 0 | M28: Asaja | N28: 0 | O28: 0 | P28: ='Ing y gtos'!BV29 -> 200
A29: Asaja | B29: 200 | D29: ='Ing y gtos'!BV29 -> 200 | E29: =D29-B29 -> 0 | M29: Servicio precios lonja | N29: 350 | O29: 360 | P29: ='Ing y gtos'!BV30 -> 360
A30: Servicio precios lonja | B30: 360 | D30: ='Ing y gtos'!BV30 -> 360 | E30: =D30-B30 -> 0 | M30: Portes | N30: 411.4 | O30: 1323.84 | P30: ='Ing y gtos'!BV31 -> 1134
A31: Portes | B31: 1134 | D31: ='Ing y gtos'!BV31 -> 1134 | E31: =D31-B31 -> 0 | M31: Comisiones corredor | N31: 1049.72 | O31: 0 | P31: ='Ing y gtos'!BV32 -> 0
A32: Comisiones corredor | B32: 0 | D32: ='Ing y gtos'!BV32 -> 0 | E32: =D32-B32 -> 0 | M32: Total pagos vacuno | N32: 15767.024 | O32: 11740.02 | P32: ='Ing y gtos'!BV33 -> 21220.57
A33: Total pagos vacuno | B33: 18704.3 | D33: ='Ing y gtos'!BV33 -> 21220.57 | E33: =D33-B33 -> 2516.27 | F33: DIMINUYE EL GASTO | M33: Check | N33: 0 | O33: 0 | P33: ='Ing y gtos'!BV34 -> 0
A34: Check | B34: 0 | D34: ='Ing y gtos'!BV34 -> 0
