Workbook

Sheet P&L
B2: Sales | F2: =F26 -> 136700 | H2: Expenses | J2: =SUM(J4,J17,J21) -> 22119.098 | L2: Profit | M2: =F2-J2 -> 114580.9
D4: Dropet | F4: NixAl | H4: Trips | J4: =SUM(J12,J5) -> 10545 | L4: Goal | M4: 130000
B5: Client | C5: Price | D5: % | E5: Eur | H5: Conferences | J5: =SUM(J6:J10) -> 6065 | L5: % vs. Goal | M5: =M2/M4 -> 0.88139155
B6: Bioagra | C6: 35000 | D6: 0.5 | E6: =C6*D6 -> 17500 | F6: =C6-E6 -> 17500 | H6: February RFA - US | J6: =850+500+500 -> 1850 | L6: Eur vs. Goal | M6: =M2-M4 -> -15419.098
B7: Verbio | C7: 15000 | D7: 0.3 | E7: =C7*D7 -> 4500 | F7: =C7-E7 -> 10500 | H7: May Dropet conference | J7: 500 | L7: Potencial | M7: =F29+F46 -> 164121.95
B8: Alco | C8: 15000 | D8: 0.3 | E8: =C8*D8 -> 4500 | F8: =C8-E8 -> 10500 | H8: May Sugar Week - US | J8: =850+500+500 -> 1850
B9: Vertex | C9: 30000 | D9: 0 | E9: =C9*D9 -> 0 | F9: =C9-E9 -> 30000 | H9: Oct Argus Bios - LDN | J9: =250+50+215 -> 515
B10: Mabanaft | C10: 5000 | D10: 0.3 | E10: =C10*D10 -> 1500 | F10: =C10-E10 -> 3500 | H10: Nov FO Licht - Brussel | J10: =550+550+250 -> 1350
B11: Vertex Ad Hoc | C11: 15000 | D11: 0 | E11: =C11*D11 -> 0 | F11: =C11-E11 -> 15000
B12: Shell | C12: 5000 | D12: 0.3 | E12: =C12*D12 -> 1500 | F12: =C12-E12 -> 3500 | H12: Others | J12: =SUM(J13:J14) -> 4480
B13: Neste | C13: 7500 | D13: 0.3 | E13: =C13*D13 -> 2250 | F13: =C13-E13 -> 5250 | H13: Madrid x 6 | J13: =(130+100+100)*6 -> 1980
B14: Enviral | C14: 18500 | D14: 0.3 | E14: =C14*D14 -> 5550 | F14: =C14-E14 -> 12950 | H14: Europe summer | J14: 2500
B15: Cramer | C15: 15000 | D15: 0.3 | E15: =C15*D15 -> 4500 | F15: =C15-E15 -> 10500
B16: Repsol | C16: 15000 | D16: 0.3 | E16: =C16*D16 -> 4500 | F16: =C16-E16 -> 10500
B17: Raizen | C17: 0 | H17: Personnel | J17: =SUM(J18:J19) -> 3300
B18: P66 | H18: Jesus López López | J18: =15000*0+(200*12) -> 2400
B19: Sucden | C19: 15000 | H19: Felipe Fontes | J19: =75*12 -> 900
B20: Ruhr | C20: 10000 | D20: 0.3 | E20: =C20*D20 -> 3000 | F20: =C20-E20 -> 7000
B21: AdBio | C21: 0 | D21: 0.3 | E21: =C21*D21 -> 0 | F21: =C21-E21 -> 0 | H21: Services | J21: =SUM(J22:J25) -> 8274.0984
B22: Sao Martinho | H22: Fiscal, HR, Accounting (Creativa) | J22: =85*12 -> 1020
B23: Kurana | H23: Legal | J23: 1000
B24: Totsa | C24: 15000 | H24: ICE | J24: =280*12/1.22 -> 2754.0984
B25: Roquette | C25: 15000 | D25: 0.3 | H25: Opis | J25: 3500
B26: Total | C26: =SUM(C6:C25) -> 231000 | E26: =SUM(E6:E25) -> 49300 | F26: =SUM(F6:F25) -> 136700
B29: Proposals | C29: =SUM(C30:C42) -> 80121.951 | E29: =SUM(E30:E42) -> 22500 | F29: =SUM(F30:F42) -> 57621.951
B30: Cepsa | C30: 0 | D30: 0 | E30: =C30*D30 -> 0 | F30: =C30-E30 -> 0
B31: Cramer | C31: 15000 | D31: 0.3 | E31: =C31*D31 -> 4500 | F31: =C31-E31 -> 10500
B32: Sucden | C32: 15000 | D32: 0.3 | E32: =C32*D32 -> 4500 | F32: =C32-E32 -> 10500
B33: Ruhr | D33: 0.3 | E33: =C33*D33 -> 0 | F33: =C33-E33 -> 0
B34: Snetor | C34: 0 | D34: 0.3 | E34: =C34*D34 -> 0 | F34: =C34-E34 -> 0
B35: Envien | C35: 15000 | D35: 0.3 | E35: =C35*D35 -> 4500 | F35: =C35-E35 -> 10500
B36: Varo | C36: 0 | D36: 0.3 | E36: =C36*D36 -> 0 | F36: =C36-E36 -> 0
B37: Totsa | C37: 15000 | D37: 0.3 | E37: =C37*D37 -> 4500 | F37: =C37-E37 -> 10500
D38: 0.3 | E38: =C38*D38 -> 0 | F38: =C38-E38 -> 0
B39: Repsol | C39: 15000 | D39: 0.3 | E39: =C39*D39 -> 4500 | F39: =C39-E39 -> 10500
B40: Kurana | C40: 0 | D40: 0.3 | E40: =C40*D40 -> 0 | F40: =C40-E40 -> 0
B41: Matt Sneyder | C41: =6300/1.23 -> 5121.9512 | D41: 0 | E41: =C41*D41 -> 0 | F41: =C41-E41 -> 5121.9512
B42: Crop | C42: 0 | D42: 0 | E42: =C42*D42 -> 0 | F42: =C42-E42 -> 0
B44: Sales & Proposals | C44: =SUM(C26,C29) -> 311121.95 | E44: =SUM(E26,E29) -> 71800 | F44: =SUM(F26,F29) -> 194321.95
B46: Prospects | C46: =SUM(C47:C56) -> 120000 | E46: =SUM(E47:E56) -> 13500 | F46: =SUM(F47:F56) -> 106500
...

Sheet Tesoreria
C2: 2018 | P2: 2019 | AC2: 2020 | AL2: 2020/2021 | AY2: 2021/2022 | BL2: 2022/2023 | BY2: 2023/2024 | CM2: 2024/2025 | CZ2: 2025/2026
B3: Previsiones Caja | C3: Ene | D3: Feb | E3: Mar | F3: Abr | G3: May | H3: Jun | I3: Jul | J3: Ago | K3: Sep | L3: Oct | M3: Nov | N3: Dic | O3: Totales | P3: Ene | Q3: Feb | R3: Mar | S3: Abr | T3: May | U3: Jun | V3: Jul | W3: Ago | X3: Sep | Y3: Oct | Z3: Nov | AA3: Dic | AB3: Totales | AC3: Ene | AD3: Feb | AE3: Mar | AF3: Abr | AG3: May | AH3: Jun | AI3: Jul | AJ3: Ago | AK3: Totales | AL3: Sep | AM3: Oct | AN3: Nov | AO3: Dic | AP3: Ene | AQ3: Feb | AR3: Mar | AS3: Abr | AT3: May | AU3: Jun | AV3: Jul | AW3: Ago | AX3: Totales | AY3: Sep | AZ3: Oct | BA3: Nov | BB3: Dic | BC3: Ene | BD3: Feb | BE3: Mar | BF3: Abr | BG3: May | BH3: Jun | BI3: Jul | BJ3: Ago | BK3: Totales | BL3: Sep | BM3: Oct | BN3: Nov | BO3: Dic | BP3: Ene | BQ3: Feb | BR3: Mar | BS3: Abr | BT3: May | BU3: Jun | BV3: Jul | BW3: Ago | BX3: Totales | BY3: Sep | BZ3: Oct | CA3: Nov | CB3: Dic | CC3: Ene | CD3: Feb | CE3: Mar | CF3: Abr | CG3: May | CH3: Jun | CI3: Jul | CJ3: Ago | CK3: Totales | CL3: Saco Ptes. | CM3: Sep | CN3: Oct | CO3: Nov | CP3: Dic | CQ3: Ene | CR3: Feb | CS3: Mar | CT3: Abr | CU3: May | CV3: Jun | CW3: Jul | CX3: Ago | CY3: Totales | CZ3: Sep | DA3: Oct | DB3: Nov | DC3: Dic | DD3: Ene | DE3: Feb | DF3: Mar | DG3: Abr | DH3: May | DI3: Jun | DJ3: Jul | DK3: Ago | DL3: Totales
B4: Cobros
B5: MKT INTELIGENCE | AK5: =SUM(AC5:AJ5) -> 0
B6: Alcodis | C6: 15000 | O6: =SUM(C6:N6) -> 15000 | Q6: 15000 | AB6: =SUM(P6:AA6) -> 15000 | AC6: 15000 | AK6: =SUM(AC6:AJ6) -> 15000 | AP6: 15000 | AX6: =SUM(AL6:AW6) -> 15000 | BC6: 15000 | BK6: =SUM(AY6:BJ6) -> 15000 | BR6: 15000 | BX6: =SUM(BL6:BW6) -> 15000 | CC6: 15000 | CK6: =SUM(BY6:CJ6) -> 15000 | CQ6: 15000 | CY6: =SUM(CM6:CX6) -> 15000 | DD6: 15000 | DL6: =SUM(CZ6:DK6) -> 15000
B7: Bioagra | D7: 35000 | O7: =SUM(C7:N7) -> 35000 | P7: 40000 | AB7: =SUM(P7:AA7) -> 40000 | AD7: 40000 | AK7: =SUM(AC7:AJ7) -> 40000 | AP7: 40000 | AX7: =SUM(AL7:AW7) -> 40000 | BE7: =40000+10000 -> 50000 | BK7: =SUM(AY7:BJ7) -> 50000 | BP7: =40000 -> 40000 | BX7: =SUM(BL7:BW7) -> 40000 | CC7: =41500 -> 41500 | CD7: =4200 -> 4200 | CK7: =SUM(BY7:CJ7) -> 45700 | CQ7: 41500 | CY7: =SUM(CM7:CX7) -> 41500 | DD7: 41500 | DL7: =SUM(CZ7:DK7) -> 41500
B8: Verbio | E8: 15000 | O8: =SUM(C8:N8) -> 15000 | V8: 9000 | AB8: =SUM(P8:AA8) -> 9000 | AE8: =9000+30000 -> 39000 | AK8: =SUM(AC8:AJ8) -> 39000 | AU8: =9000 -> 9000 | AV8: 30000 | AX8: =SUM(AL8:AW8) -> 39000 | BF8: =9000+30000 -> 39000 | BK8: =SUM(AY8:BJ8) -> 39000 | BQ8: 15000 | BX8: =SUM(BL8:BW8) -> 15000 | CF8: =15000+4300 -> 19300 | CK8: =SUM(BY8:CJ8) -> 19300 | CR8: 15000 | CY8: =SUM(CM8:CX8) -> 15000 | DE8: 15000 | DL8: =SUM(CZ8:DK8) -> 15000
B9: Vertex | E9: 0 | F9: 0 | G9: 0 | H9: 0 | O9: =SUM(C9:N9) -> 0 | Z9: =15000*1.21 -> 18150 | AB9: =SUM(P9:AA9) -> 18150 | AC9: 15000 | AK9: =SUM(AC9:AJ9) -> 15000 | AR9: =25000 -> 25000 | AX9: =SUM(AL9:AW9) -> 25000 | BA9: 25000 | BF9: =25000 -> 25000 | BK9: =SUM(AY9:BJ9) -> 50000 | BN9: =50000*0 -> 0 | BP9: =25000 -> 25000 | BS9: 25000 | BX9: =SUM(BL9:BW9) -> 50000 | CB9: 25000 | CF9: =4200+25000 -> 29200 | CK9: =SUM(BY9:CJ9) -> 54200 | CP9: 25000 | CT9: 25000 | CY9: =SUM(CM9:CX9) -> 50000 | DC9: 25000 | DG9: 25000 | DL9: =SUM(CZ9:DK9) -> 50000
B10: Shell | I10: 5000 | O10: =SUM(C10:N10) -> 5000 | V10: 4500 | AB10: =SUM(P10:AA10) -> 4500 | AG10: =4500 -> 4500 | AK10: =SUM(AC10:AJ10) -> 4500 | AP10: =4500 -> 4500 | AQ10: =4500 -> 4500 | AX10: =SUM(AL10:AW10) -> 9000 | AZ10: 4500 | BC10: 4500 | BK10: =SUM(AY10:BJ10) -> 9000 | BO10: 6000 | BS10: 6000 | BX10: =SUM(BL10:BW10) -> 12000 | BY10: 6000 | CB10: 6000 | CI10: 6000 | CK10: =SUM(BY10:CJ10) -> 18000 | CP10: 6000 | CW10: 6000 | CY10: =SUM(CM10:CX10) -> 12000 | DC10: 6000 | DJ10: 6000 | DL10: =SUM(CZ10:DK10) -> 12000
B11: Ruhr | J11: 10000 | O11: =SUM(C11:N11) -> 10000 | X11: 10000 | AB11: =SUM(P11:AA11) -> 10000 | AK11: =SUM(AC11:AJ11) -> 0 | AL11: 10000 | AX11: =SUM(AL11:AW11) -> 10000 | AZ11: 10000 | BK11: =SUM(AY11:BJ11) -> 10000 | BL11: 10000 | BW11: 10500 | BX11: =SUM(BL11:BW11) -> 20500 | CJ11: 10500 | CK11: =SUM(BY11:CJ11) -> 10500 | CX11: 10500 | CY11: =SUM(CM11:CX11) -> 10500 | DK11: 10500 | DL11: =SUM(CZ11:DK11) -> 10500
B12: Cremer | M12: 7500 | O12: =SUM(C12:N12) -> 7500 | U12: 7500 | Y12: 7500 | AB12: =SUM(P12:AA12) -> 15000 | AG12: 7500 | AK12: =SUM(AC12:AJ12) -> 7500 | AN12: 7500 | AR12: 7500 | AX12: =SUM(AL12:AW12) -> 15000 | BA12: 7500 | BF12: 7500 | BK12: =SUM(AY12:BJ12) -> 15000 | BO12: 7500 | BR12: 7500 | BX12: =SUM(BL12:BW12) -> 15000 | CK12: =SUM(BY12:CJ12) -> 0 | CY12: =SUM(CM12:CX12) -> 0 | DL12: =SUM(CZ12:DK12) -> 0
B13: Lantmannen | O13: =SUM(C13:N13) -> 0 | P13: 10000 | AB13: =SUM(P13:AA13) -> 10000 | AI13: 12500 | AK13: =SUM(AC13:AJ13) -> 12500 | AR13: 10000 | AX13: =SUM(AL13:AW13) -> 10000 | BE13: 10000 | BK13: =SUM(AY13:BJ13) -> 10000 | BR13: 12500 | BX13: =SUM(BL13:BW13) -> 12500 | CD13: 12000 | CK13: =SUM(BY13:CJ13) -> 12000 | CR13: 12000 | CY13: =SUM(CM13:CX13) -> 12000 | DE13: 12000 | DL13: =SUM(CZ13:DK13) -> 12000
B14: Neste | O14: =SUM(C14:N14) -> 0 | Q14: 6000 | V14: 6000 | AB14: =SUM(P14:AA14) -> 12000 | AD14: 6000 | AJ14: 6000 | AK14: =SUM(AC14:AJ14) -> 12000 | AQ14: 6000 | AX14: =SUM(AL14:AW14) -> 6000 | AY14: 6000 | BF14: 6000 | BJ14: 6000 | BK14: =SUM(AY14:BJ14) -> 18000 | BQ14: 6000 | BV14: 6000 | BX14: =SUM(BL14:BW14) -> 12000 | CK14: =SUM(BY14:CJ14) -> 0 | CY14: =SUM(CM14:CX14) -> 0 | DL14: =SUM(CZ14:DK14) -> 0
B15: Mabanaft | G15: 0 | H15: 5000 | O15: =SUM(C15:N15) -> 5000 | X15: =5000+5000 -> 10000 | AB15: =SUM(P15:AA15) -> 10000 | AD15: -5000 | AK15: =SUM(AC15:AJ15) -> -5000 | AX15: =SUM(AL15:AW15) -> 0 | BK15: =SUM(AY15:BJ15) -> 0 | BX15: =SUM(BL15:BW15) -> 0 | CK15: =SUM(BY15:CJ15) -> 0 | CY15: =SUM(CM15:CX15) -> 0 | DL15: =SUM(CZ15:DK15) -> 0
B16: Sucden | O16: =SUM(C16:N16) -> 0 | S16: 4500 | AB16: =SUM(P16:AA16) -> 4500 | AI16: 4500 | AK16: =SUM(AC16:AJ16) -> 4500 | AX16: =SUM(AL16:AW16) -> 0 | BB16: 10000 | BK16: =SUM(AY16:BJ16) -> 10000 | BX16: =SUM(BL16:BW16) -> 0 | BY16: =5285+5715 -> 11000 | CF16: 4200 | CK16: =SUM(BY16:CJ16) -> 15200 | CX16: 6000 | CY16: =SUM(CM16:CX16) -> 6000 | DK16: 6000 | DL16: =SUM(CZ16:DK16) -> 6000
B17: Roquette | O17: =SUM(C17:N17) -> 0 | Q17: 12500 | AB17: =SUM(P17:AA17) -> 12500 | AC17: =12500 -> 12500 | AK17: =SUM(AC17:AJ17) -> 12500 | AN17: =12500*0 -> 0 | AX17: =SUM(AL17:AW17) -> 0 | BK17: =SUM(AY17:BJ17) -> 0 | BX17: =SUM(BL17:BW17) -> 0 | CK17: =SUM(BY17:CJ17) -> 0 | CY17: =SUM(CM17:CX17) -> 0 | DL17: =SUM(CZ17:DK17) -> 0
B18: Greenergy | O18: =SUM(C18:N18) -> 0 | AB18: =SUM(P18:AA18) -> 0 | AF18: 12000 | AK18: =SUM(AC18:AJ18) -> 12000 | AU18: 12000 | AX18: =SUM(AL18:AW18) -> 12000 | BE18: 12000 | BK18: =SUM(AY18:BJ18) -> 12000 | BR18: 12000 | BX18: =SUM(BL18:BW18) -> 12000 | CD18: 13200 | CK18: =SUM(BY18:CJ18) -> 13200 | CR18: 13200 | CY18: =SUM(CM18:CX18) -> 13200 | DE18: 13200 | DL18: =SUM(CZ18:DK18) -> 13200
B19: Agrana | O19: =SUM(C19:N19) -> 0 | V19: 12500 | AB19: =SUM(P19:AA19) -> 12500 | AK19: =SUM(AC19:AJ19) -> 0 | AM19: 11500 | AW19: 12500 | AX19: =SUM(AL19:AW19) -> 24000 | BK19: =SUM(AY19:BJ19) -> 0 | BL19: 11500 | BV19: 12000 | BX19: =SUM(BL19:BV19) -> 23500 | CJ19: 12000 | CK19: =SUM(BY19:CJ19) -> 12000 | CX19: 12000 | CY19: =SUM(CM19:CX19) -> 12000 | DK19: 12000 | DL19: =SUM(CZ19:DK19) -> 12000
B20: SCA | O20: =SUM(C20:N20) -> 0 | T20: 7069.18 | AB20: =SUM(P20:AA20) -> 7069.18 | AI20: =4000/1.1608 -> 3445.8994 | AK20: =SUM(AC20:AJ20) -> 3445.8994 | AT20: =5000/1.2059 -> 4146.2808 | AX20: =SUM(AL20:AW20) -> 4146.2808 | BH20: =6000/1.0726 -> 5593.884 | BK20: =SUM(AY20:BJ20) -> 5593.884 | BS20: =6000/1.094 -> 5484.4607 | BX20: =SUM(BL20:BW20) -> 5484.4607 | CF20: =6000/1 -> 6000 | CK20: =SUM(BY20:CJ20) -> 6000 | CT20: 6000 | CY20: =SUM(CM20:CX20) -> 6000 | DG20: 6000 | DL20: =SUM(CZ20:DK20) -> 6000
B21: Raizen | O21: =SUM(C21:N21) -> 0 | AB21: =SUM(P21:AA21) -> 0 | AK21: =SUM(AC21:AJ21) -> 0 | AL21: 22000 | AV21: =22000/1.1767 -> 18696.354 | AX21: =SUM(AL21:AW21) -> 40696.354 | BF21: =22000/1.083 -> 20313.943 | BK21: =SUM(AY21:BJ21) -> 20313.943 | BR21: =22000/1.0875 -> 20229.885 | BX21: =SUM(BL21:BW21) -> 20229.885 | CF21: =22000/1 -> 22000 | CK21: =SUM(BY21:CJ21) -> 22000 | CS21: =22000/1 -> 22000 | CY21: =SUM(CM21:CX21) -> 22000 | DF21: =22000/1 -> 22000 | DL21: =SUM(CZ21:DK21) -> 22000
B22: Repsol | O22: =SUM(C22:N22) -> 0 | S22: =15000*1.21 -> 18150 | AB22: =SUM(P22:AA22) -> 18150 | AK22: =SUM(AC22:AJ22) -> 0 | AM22: =15000*1.21 -> 18150 | AT22: =15000*1.21 -> 18150 | AX22: =SUM(AL22:AW22) -> 36300 | BD22: =3750*1.21 -> 4537.5 | BH22: =15000*1.21 -> 18150 | BK22: =SUM(AY22:BJ22) -> 22687.5 | BS22: =16500*1.21 -> 19965 | BX22: =SUM(BL22:BW22) -> 19965 | CG22: =16900*1.21 -> 20449 | CK22: =SUM(BY22:CJ22) -> 20449 | CT22: 16500 | CY22: =SUM(CM22:CX22) -> 16500 | DG22: =16500 -> 16500 | DL22: =SUM(CZ22:DK22) -> 16500
B23: Amerra | O23: =SUM(C23:N23) -> 0 | W23: 10771.99 | AB23: =SUM(P23:AA23) -> 10771.99 | AG23: =9000/1.0792 -> 8339.5107 | AK23: =SUM(AC23:AJ23) -> 8339.5107 | AX23: =SUM(AL23:AW23) -> 0 | BK23: =SUM(AY23:BJ23) -> 0 | BX23: =SUM(BL23:BW23) -> 0 | CK23: =SUM(BY23:CJ23) -> 0 | CY23: =SUM(CM23:CX23) -> 0 | DL23: =SUM(CZ23:DK23) -> 0
B24: Amerra -RAA | AB24: =SUM(P24:AA24) -> 0 | AK24: =SUM(AC24:AJ24) -> 0 | AX24: =SUM(AL24:AW24) -> 0 | BI24: =15000/1.0005 -> 14992.504 | BK24: =SUM(AY24:BJ24) -> 14992.504 | BM24: =15000/1.0037 -> 14944.705 | BS24: =15000/1.0978 -> 13663.691 | BX24: =SUM(BL24:BW24) -> 28608.396 | CA24: =15000/1.0741 -> 13965.18 | CG24: =15000/1 -> 15000 | CK24: =SUM(BY24:CJ24) -> 28965.18 | CO24: =15000/1 -> 15000 | CT24: =15000/1 -> 15000 | CY24: =SUM(CM24:CX24) -> 30000 | DB24: =15000/1 -> 15000 | DG24: =15000/1 -> 15000 | DL24: =SUM(CZ24:DK24) -> 30000
B25: Amerra -SBA | AB25: =SUM(P25:AA25) -> 0 | AK25: =SUM(AC25:AJ25) -> 0 | AX25: =SUM(AL25:AW25) -> 0 | BI25: =5000/1.0425 -> 4796.1631 | BK25: =SUM(AY25:BJ25) -> 4796.1631 | BM25: =5000/0.986 -> 5070.9939 | BU25: =5000/1.0951 -> 4565.7931 | BX25: =SUM(BL25:BW25) -> 9636.787 | BZ25: =(5000-15)/1.053+15/1.0538 -> 4748.3273 | CG25: 5000 | CK25: =SUM(BY25:CJ25) -> 9748.3273 | CO25: 5000 | CT25: 5000 | CY25: =SUM(CM25:CX25) -> 10000 | DB25: 5000 | DG25: 5000 | DL25: =SUM(CZ25:DK25) -> 10000
B26: Varo | O26: =SUM(C26:N26) -> 0 | T26: 12500 | AB26: =SUM(P26:AA26) -> 12500 | AG26: 12500 | AK26: =SUM(AC26:AJ26) -> 12500 | AW26: 0 | AX26: =SUM(AL26:AW26) -> 0 | BK26: =SUM(AY26:BJ26) -> 0 | BX26: =SUM(BL26:BW26) -> 0 | CK26: =SUM(BY26:CJ26) -> 0 | CY26: =SUM(CM26:CX26) -> 0 | DL26: =SUM(CZ26:DK26) -> 0
B27: Enviral | M27: 18500 | O27: =SUM(C27:N27) -> 18500 | AB27: =SUM(P27:AA27) -> 0 | AG27: 18500 | AK27: =SUM(AC27:AJ27) -> 18500 | AN27: 18500 | AX27: =SUM(AL27:AW27) -> 18500 | BA27: 18500 | BK27: =SUM(AY27:BJ27) -> 18500 | BN27: 15000 | BX27: =SUM(BL27:BW27) -> 15000 | CA27: 15000 | CK27: =SUM(BY27:CJ27) -> 15000 | CN27: 15000 | CY27: =SUM(CM27:CX27) -> 15000 | DA27: 15000 | DL27: =SUM(CZ27:DK27) -> 15000
B28: Vivergo | O28: =SUM(C28:N28) -> 0 | V28: 12500 | AB28: =SUM(P28:AA28) -> 12500 | AJ28: 12500 | AK28: =SUM(AC28:AJ28) -> 12500 | AV28: 12500 | AX28: =SUM(AL28:AW28) -> 12500 | BK28: =SUM(AY28:BJ28) -> 0 | BL28: 12500 | BW28: 14000 | BX28: =SUM(BL28:BW28) -> 26500 | CI28: 14000 | CK28: =SUM(BY28:CJ28) -> 14000 | CW28: 14000 | CY28: =SUM(CM28:CX28) -> 14000 | DJ28: 14000 | DL28: =SUM(CZ28:DK28) -> 14000
B29: Neot | O29: =SUM(C29:N29) -> 0 | Y29: =500*12 -> 6000 | AB29: =SUM(P29:AA29) -> 6000 | AH29: 6000 | AK29: =SUM(AC29:AJ29) -> 6000 | AX29: =SUM(AL29:AW29) -> 0 | BA29: 8000 | BH29: 8000 | BK29: =SUM(AY29:BJ29) -> 16000 | BW29: 12000 | BX29: =SUM(BL29:BW29) -> 12000 | CI29: 12000 | CK29: =SUM(BY29:CJ29) -> 12000 | CW29: 12000 | CY29: =SUM(CM29:CX29) -> 12000 | DJ29: 12000 | DL29: =SUM(CZ29:DK29) -> 12000
B30: Panonnia | O30: =SUM(C30:N30) -> 0 | Y30: 10000 | AB30: =SUM(P30:AA30) -> 10000 | AK30: =SUM(AC30:AJ30) -> 0 | AN30: 12500 | AX30: =SUM(AL30:AW30) -> 12500 | BA30: 12500 | BK30: =SUM(AY30:BJ30) -> 12500 | BN30: 12500 | BX30: =SUM(BL30:BW30) -> 12500 | CB30: 12500 | CF30: =4200 -> 4200 | CK30: =SUM(BY30:CJ30) -> 16700 | CN30: 12500 | CY30: =SUM(CM30:CX30) -> 12500 | DA30: 12500 | DL30: =SUM(CZ30:DK30) -> 12500
B31: Marquis | O31: =SUM(C31:N31) -> 0 | AB31: =SUM(P31:AA31) -> 0 | AD31: =4570.32 -> 4570.32 | AK31: =SUM(AC31:AJ31) -> 4570.32 | AO31: =4109.32-1 -> 4108.32 | AX31: =SUM(AL31:AW31) -> 4108.32 | AZ31: =5041.8/1.1603+1933.2/1.1603 -> 6011.3764 | BK31: =SUM(AY31:BJ31) -> 6011.3764 | BR31: =9708.56/1.0586 -> 9171.1317 | BS31: =(10000-9708.56)/1.0972 -> 265.62158 | BX31: =SUM(BL31:BW31) -> 9436.7533 | BZ31: =10000/1.0569 -> 9461.6331 | CK31: =SUM(BY31:CJ31) -> 9461.6331 | CO31: 10000 | CY31: =SUM(CM31:CX31) -> 10000 | DB31: 10000 | DL31: =SUM(CZ31:DK31) -> 10000
B32: FC Betterave (Cristalco) | O32: =SUM(C32:N32) -> 0 | Y32: =12500*1.21 -> 15125 | AB32: =SUM(P32:AA32) -> 15125 | AK32: =SUM(AC32:AJ32) -> 0 | AM32: =12500*1.21 -> 15125 | AX32: =SUM(AL32:AW32) -> 15125 | AZ32: =12500*1.21 -> 15125 | BK32: =SUM(AY32:BJ32) -> 15125 | BN32: =12500*1.21 -> 15125 | BX32: =SUM(BL32:BW32) -> 15125 | CA32: =13000*1.21 -> 15730 | CK32: =SUM(BY32:CJ32) -> 15730 | CO32: 13000 | CY32: =SUM(CM32:CX32) -> 13000 | DB32: 13000 | DL32: =SUM(CZ32:DK32) -> 13000
B33: Redwood Group | O33: =SUM(C33:N33) -> 0 | AB33: =SUM(P33:AA33) -> 0 | AF33: 9074.41 | AI33: 4208.4 | AK33: =SUM(AC33:AJ33) -> 13282.81 | AT33: =5000/1.206+3000/1.206+3000/1.206 -> 9121.0614 | AW33: =3000/1.1736 -> 2556.2372 | AX33: =SUM(AL33:AW33) -> 11677.299 | BA33: =3000/1.1368 -> 2638.9866 | BF33: =3000/1.1052 -> 2714.4408 | BG33: =3000/1.0524 -> 2850.6271 | BI33: =3000/1.0124 -> 2963.2556 | BK33: =SUM(AY33:BJ33) -> 11167.31 | BM33: =3000/0.9778 -> 3068.1121 | BQ33: =3000/1.07 -> 2803.7383 | BS33: =3000/1.1002 -> 2726.7769 | BV33: =3000/1.1059 -> 2712.7227 | BX33: =SUM(BL33:BV33) -> 11311.35 | BZ33: =3000/1.0597 -> 2830.9899 | CK33: =SUM(BY33:CJ33) -> 2830.9899 | CY33: =SUM(CM33:CX33) -> 0 | DL33: =SUM(CZ33:DK33) -> 0
B34: Nordzucker AG | O34: =SUM(C34:N34) -> 0 | AB34: =SUM(P34:AA34) -> 0 | AF34: 5000 | AK34: =SUM(AC34:AJ34) -> 5000 | AP34: 5000 | AX34: =SUM(AL34:AW34) -> 5000 | BD34: 5000 | BK34: =SUM(AY34:BJ34) -> 5000 | BR34: 5000 | BX34: =SUM(BL34:BW34) -> 5000 | CD34: 5500 | CK34: =SUM(BY34:CJ34) -> 5500 | CR34: 5500 | CY34: =SUM(CM34:CX34) -> 5500 | DE34: 5500 | DL34: =SUM(CZ34:DK34) -> 5500
B35: Castleton Commodities Int. LLC | O35: =SUM(C35:N35) -> 0 | AB35: =SUM(P35:AA35) -> 0 | AH35: =8000/1.1285 -> 7089.0563 | AK35: =SUM(AC35:AJ35) -> 7089.0563 | AX35: =SUM(AL35:AW35) -> 0 | AZ35: =7987/1.16 -> 6885.3448 | BK35: =SUM(AZ35:BJ35) -> 6885.3448 | BX35: =SUM(BL35:BW35) -> 0 | CK35: =SUM(BY35:CJ35) -> 0 | CY35: =SUM(CM35:CX35) -> 0 | DL35: =SUM(CZ35:DK35) -> 0
B36: OCI FUELS B.V. | O36: =SUM(C36:N36) -> 0 | AB36: 0 | AI36: 22000 | AK36: =SUM(AC36:AJ36) -> 22000 | AX36: =SUM(AL36:AW36) -> 0 | BB36: 22000 | BJ36: 22000 | BK36: =SUM(BB36:BJ36) -> 44000 | BW36: 16500 | BX36: =SUM(BL36:BW36) -> 16500 | CI36: 16500 | CK36: =SUM(BY36:CJ36) -> 16500 | CW36: 16500 | CY36: =SUM(CM36:CX36) -> 16500 | DJ36: 16500 | DL36: =SUM(CZ36:DK36) -> 16500
B37: Poet | AB37: 0 | AK37: =SUM(AC37:AJ37) -> 0 | AP37: =(7000-33)/1.2166-27.87/1.224 -> 5703.8455 | AQ37: =21.87/1.224 -> 17.867647 | AX37: =SUM(AL37:AW37) -> 5721.7132 | BC37: =(7000-335.72)/1.116 -> 5971.5771 | BJ37: 0 | BK37: =SUM(AY37:BJ37) -> 5971.5771 | BP37: =11720.21/1.0903 -> 10749.528 | BQ37: =280/1.0988 -> 254.82344 | BX37: =SUM(BL37:BW37) -> 11004.351 | CF37: =15000/1 -> 15000 | CK37: =SUM(BY37:CJ37) -> 15000 | CQ37: =15000/1 -> 15000 | CY37: =SUM(CM37:CX37) -> 15000 | DD37: =15000/1 -> 15000 | DL37: =SUM(CZ37:DK37) -> 15000
B38: OMV | AB38: 0 | AK38: =SUM(AC38:AJ38) -> 0 | AW38: =7600+13000 -> 20600 | AX38: =SUM(AL38:AW38) -> 20600 | BK38: =SUM(AY38:BJ38) -> 0 | BR38: =15000+15000 -> 30000 | BX38: =SUM(BL38:BW38) -> 30000 | CK38: =SUM(BY38:CJ38) -> 0 | CS38: =15000+15000 -> 30000 | CY38: =SUM(CM38:CX38) -> 30000 | DL38: =SUM(CZ38:DK38) -> 0
B39: Totsa | AB39: 0 | AK39: =SUM(AC39:AJ39) -> 0 | AX39: =SUM(AL39:AW39) -> 0 | AY39: 24000 | BK39: =SUM(AY39:BJ39) -> 24000 | BN39: 24000 | BX39: =SUM(BL39:BW39) -> 24000 | BZ39: 36000 | CK39: =SUM(BZ39:CJ39) -> 36000 | CQ39: 24000 | CY39: =SUM(CM39:CX39) -> 24000 | DD39: 24000 | DL39: =SUM(CZ39:DK39) -> 24000
B40: Trafigura | AB40: 0 | AK40: =SUM(AC40:AJ40) -> 0 | AX40: =SUM(AL40:AW40) -> 0 | BD40: 15000 | BK40: =SUM(AY40:BJ40) -> 15000 | BQ40: 15000 | BX40: =SUM(BL40:BW40) -> 15000 | BZ40: 15900 | CK40: =SUM(BY40:CJ40) -> 15900 | CO40: 15900 | CY40: =SUM(CM40:CX40) -> 15900 | DB40: 15900 | DL40: =SUM(CZ40:DK40) -> 15900
B41: Ethanol Energy | AB41: 0 | AK41: =SUM(AC41:AJ41) -> 0 | AX41: =SUM(AL41:AW41) -> 0 | BD41: 10000 | BK41: =SUM(AY41:BJ41) -> 10000 | BQ41: 10000 | BX41: =SUM(BL41:BW41) -> 10000 | CD41: 10000 | CK41: =SUM(BY41:CJ41) -> 10000 | CR41: 10000 | CY41: =SUM(CM41:CX41) -> 10000 | DE41: 10000 | DL41: =SUM(CZ41:DK41) -> 10000
...

Sheet Resumen cierre
A3: Previsiones Caja | B3: Totales Agosto 2021 | C3: Totales Agosto 2022 | D3: Totales a cierre Febrero 2023 | E3: Totales a cierre Agosto 2023 | F3: diferencia
A4: Cobros
A5: MKT INTELIGENCE | B5: 0
A6: Alcodis | B6: 15000 | C6: 15000 | D6: 15000 | E6: 15000 | F6: =E6-D6 -> 0
A7: Bioagra | B7: 40000 | C7: 50000 | D7: 40000 | E7: 40000 | F7: =E7-D7 -> 0
A8: Verbio | B8: 39000 | C8: 39000 | D8: 15000 | E8: 15000 | F8: =E8-D8 -> 0
A9: Vertex | B9: 25000 | C9: 50000 | D9: 50000 | E9: 50000 | F9: =E9-D9 -> 0
A10: Shell | B10: 9000 | C10: 9000 | D10: 12000 | E10: 12000 | F10: =E10-D10 -> 0
A11: Ruhr | B11: 10000 | C11: 10000 | D11: 10000 | E11: 20500 | F11: =E11-D11 -> 10500
A12: Cremer | B12: 15000 | C12: 15000 | D12: 15000 | E12: 15000 | F12: =E12-D12 -> 0
A13: Lantmannen | B13: 10000 | C13: 10000 | D13: 12500 | E13: 12500 | F13: =E13-D13 -> 0
A14: Neste | B14: 6000 | C14: 18000 | D14: 12000 | E14: 12000 | F14: =E14-D14 -> 0
A15: Mabanaft | B15: 0 | C15: 0 | D15: 0 | E15: 0 | F15: =E15-D15 -> 0
A16: Sucden | B16: 0 | C16: 10000 | D16: 7500 | E16: 0 | F16: =E16-D16 -> -7500
A17: Roquette | B17: 0 | C17: 0 | D17: 0 | E17: 0 | F17: =E17-D17 -> 0
... A46: Harvestone Commodities, LLC | B46: 0 | C46: 0 | D46: 12272.448 | E46: 12272.448 | F46: =E46-D46 -> 0
A47: Almagest EAD | B47: 0 | C47: 0 | E47: 9000 | F47: =E47-D47 -> 9000
A48: AdHoc | E48: 0 | F48: =E48-D48 -> 0
A49: Dropet Intertrading | B49: 0 | C49: 0 | D49: 0 | E49: 0 | F49: =E49-D49 -> 0
A50: Repsol | B50: 0 | C50: 0 | D50: 0 | E50: 0 | F50: =E50-D50 -> 0
A51: Vertex | B51: 0 | C51: 0 | D51: 0 | E51: 0 | F51: =E51-D51 -> 0
A52: Cepsa | B52: 0 | C52: 0 | D52: 0 | E52: 0 | F52: =E52-D52 -> 0
A53: Guidepoint | B53: 0 | C53: 650 | D53: 0 | E53: 273.33 | F53: =E53-D53 -> 273.33
A54: DWS Alternatives Global Limited-PEIF | B54: 22290.5 | C54: 0 | D54: 0 | E54: 0 | F54: =E54-D54 -> 0
A55: Tomsa Destil, S.L. | B55: 2663.9723 | C55: 0 | D55: 0 | E55: 0 | F55: =E55-D55 -> 0
A56: BROKERAGE | E56: 0 | F56: =E56-D56 -> 0
A57: Enviral | B57: 0 | C57: 0 | D57: 0 | E57: 0 | F57: =E57-D57 -> 0
A58: Interalco | B58: 0 | C58: 0 | D58: 0 | E58: 0 | F58: =E58-D58 -> 0
A59: Murex | B59: 0 | C59: 0 | D59: 0 | E59: 0 | F59: =E59-D59 -> 0
A60: Seaboard | B60: 12492.713 | C60: 0 | D60: 0 | E60: 0 | F60: =E60-D60 -> 0
A61: Cremer | B61: 12781.648 | C61: 16839.811 | D61: 0 | E61: 0 | F61: =E61-D61 -> 0
A62: ACA Bio | B62: 11413.551 | C62: 6596.2788 | D62: 20735.37 | E62: 17403.518 | F62: =E62-D62 -> -3331.8521
A63: CCI - Castleton Commodities Int LLC | B63: 9617.835 | C63: 0 | D63: 0 | E63: 0 | F63: =E63-D63 -> 0
A64: Ruhr Petrol | B64: 12228.95 | C64: 40287.336 | D64: 0 | E64: 0 | F64: =E64-D64 -> 0
A65: Bioagra | B65: 2859 | C65: 0 | D65: 0 | E65: 0 | F65: =E65-D65 -> 0
A66: Czanikow | B66: 0 | C66: 143461.32 | D66: 60575.916 | E66: 40575.916 | F66: =E66-D66 -> -20000
A67: EDF Trading | C67: 0 | D67: 20000 | E67: 18511.139 | F67: =E67-D67 -> -1488.8607
A68: FUTUROS | E68: 0 | F68: =E68-D68 -> 0
A69: Paragon | B69: 77935.59 | C69: 1339426.1 | D69: -598605.73 | E69: -674077.45 | F69: =E69-D69 -> -75471.719
A70: FC Stone | B70: 0 | C70: 0 | D70: 0 | E70: 0 | F70: =E70-D70 -> 0
...

Sheet Clientes
B2: Client | C2: Eur/year | D2: EUR/USD | E2: Duration (yrs) | F2: Begins | G2: Ends | I2: Comments
B3: Alcodis | C3: 16000 | D3: EUR | E3: 1 | F3: 46023 | G3: =F3+365 -> 46388 | L3: Stocks ARA | M3: 17982 | N3: 19144.44 | O3: 20484.55 | P3: =+O3/1.18 -> 17359.788
B4: Bioagra | C4: 41500 | D4: EUR | E4: 2 | F4: 46023 | G4: =F4+365+364 -> 46752 | I4: +4,2k stocks ARA | L4: Per user | M4: =+M3/4 -> 4495.5 | N4: =+N3/4 -> 4786.11 | O4: =+O3/4 -> 5121.1375 | P4: =+P3/4 -> 4339.947
B5: Verbio | C5: 16000 | D5: EUR | E5: 1 | F5: 46023 | G5: =F5+364 -> 46387 | I5: +4,2k stocks ARA | L5: Bioagra | M5: =+M4 -> 4495.5 | N5: =+N4 -> 4786.11 | O5: =+O4 -> 5121.1375 | P5: =+P4 -> 4339.947
B6: Vertex | C6: 50000 | D6: EUR | E6: 1 | F6: 46388 | G6: =F6+364 -> 46752 | I6: 2 invoices of 25000 +4,5k stocks ARA | L6: Verbio | M6: =+M5 -> 4495.5 | N6: =+N5 -> 4786.11 | O6: =+O5 -> 5121.1375 | P6: =+P5 -> 4339.947
B7: Shell | C7: 13000 | D7: EUR | E7: 1 | F7: 45809 | G7: =F7+364 -> 46173 | I7: 2 invoices of 6000 | J7: Enviado email | L7: Panonnia | M7: =+M6 -> 4495.5 | N7: =+N6 -> 4786.11 | O7: =+O6 -> 5121.1375 | P7: =+P6 -> 4339.947
B8: Ruhr | C8: 9000 | D8: EUR | E8: 1 | F8: 45870 | G8: =F8+364 -> 46234 | L8: Vertex | M8: =+M7 -> 4495.5 | N8: =+N7 -> 4786.11 | O8: =+O7 -> 5121.1375 | P8: =+P7 -> 4339.947
B9: CREMER | C9: 0 | D9: EUR | E9: 0 | I9: Dejaron el desk de etanol | L9: Sucden | M9: =+M8 -> 4495.5 | N9: =+N8 -> 4786.11 | O9: =+O8 -> 5121.1375 | P9: =+P8 -> 4339.947
B10: Lantmannen | C10: 12000 | D10: EUR | E10: 1 | F10: 46023 | G10: =F10+364 -> 46387 | L10: Total | M10: =SUM(M5:M9) -> 22477.5 | N10: =SUM(N5:N9) -> 23930.55 | O10: =SUM(O5:O9) -> 25605.688 | P10: =SUM(P5:P9) -> 21699.735
B11: Neste Oil | C11: 0 | D11: EUR | E11: 0 | I11: Dejaron el desk de etanol
B12: Mabanaft | C12: 0 | D12: EUR | E12: 0 | I12: Dejaron el desk de etanol
B13: Sucden | C13: 5500 | D13: EUR | E13: 2 | F13: 45748 | G13: =F13+365 -> 46113 | I13: +4,2k stock ARA
B14: Roquette | C14: =12500*0 -> 0 | D14: EUR | E14: 2 | I14: Me comunicaron baja el 26/11/20 para probar FO Licht
B15: Agrana | C15: =+(12500+11500)/2 -> 12000 | D15: EUR | E15: 2 | F15: 45717 | G15: =F15+(365*2) -> 46447
B16: Repsol | C16: =16500*0 -> 0 | D16: EUR | I16: Baja 4/2/25
B17: Enviral | C17: 16975 | D17: EUR | E17: 3 | F17: 45566 | G17: =F17+(365*E17) -> 46661
B18: SCA | C18: 8500 | D18: USD | E18: 1 | F18: 45748 | G18: =F18+364 -> 46112
B19: Varo | C19: 15000 | D19: EUR | E19: 2 | F19: 45505 | G19: =+F19+(365*2) -> 46235
B20: Amerra-RAA | C20: 42000 | D20: USD | E20: 2 | F20: 45383 | G20: =F20+(365*2) -> 46113 | I20: 2 invoices/year
B21: Vivergo | C21: 14000 | D21: EUR | E21: 2 | F21: 45809 | G21: =F21+364 -> 46173
B22: NEOT | C22: 12600 | D22: EUR | E22: 2 | F22: 45809 | G22: =F22+364 -> 46173
B23: Panonnia | C23: 14000 | D23: EUR | E23: 1 | F23: 45931 | G23: =F23+364 -> 46295 | I23: +4,2k stocks ARA
B24: Marquis | C24: 11000 | D24: USD | E24: 3 | F24: 45931 | G24: =F24+364*3 -> 47023 | I24: 3 year gentelmen agreement
B25: Cristal Union | C25: 12500 | D25: EUR | E25: 1 | F25: 45931 | G25: =F25+364 -> 46295
B26: Greenergy | C26: 14000 | D26: EUR | E26: 1 | F26: 46023 | G26: =F26+364 -> 46387
B27: Redwood | D27: USD | E27: 0
B28: Nordzucker | C28: 6000 | D28: EUR | E28: 1 | F28: 46023 | G28: =F28+364 -> 46387
A29: ok | B29: Raizen | C29: 16500 | D29: USD | E29: 1 | F29: 45658 | G29: =F29+364 -> 46022 | I29: Facturar en abril
B30: CCI | C30: =8000*0 -> 0 | D30: USD | E30: 0
B31: OCI | C31: 16500 | D31: EUR | E31: 1 | F31: 45839 | G31: =F31+364 -> 46203
B32: Poet | C32: 16000 | D32: USD | E32: 1 | F32: 46023 | G32: =F32+364 -> 46387
B33: OMV | C33: 16500 | D33: EUR | E33: 2 | F33: 46023 | G33: =+F33+364 -> 46387 | K33: =12+7 -> 19
B34: TOTSA | C34: 24480 | D34: EUR | E34: 1 | F34: 46023 | G34: =+F34+364 -> 46387 | K34: 15000 | L34: =+K34/12 -> 1250
B35: Trafigura | C35: 16200 | D35: EUR | E35: 1 | F35: 45931 | G35: =+F35+364 -> 46295 | L35: =+L34*19 -> 23750
B36: Ethanol Energy | C36: =10000*0 -> 0 | D36: EUR | E36: 3
B37: Pantaleon | C37: =12000*0 -> 0 | D37: USD | E37: 1 | I37: Baja feb 26
B38: KWST | C38: =4000*0 -> 0 | D38: EUR | E38: 0 | I38: Baja
B39: EDF | D39: EUR | E39: 1 | I39: Baja, salen de etnaol
B40: Liquin | C40: 8000 | D40: EUR | E40: 3 | F40: 45809 | G40: =+F40+365+365+365 -> 46904 | I40: three year agreement
B41: Harvestone | C41: 15000 | D41: USD | E41: 1 | F41: 45931 | G41: =+F41+364 -> 46295
...

Sheet Consolidado
C1: 2023/2024 | P1: 2024/2025 | AC1: 2025/2026 | AP1: 2026/2027
C2: Sep | D2: Oct | E2: Nov | F2: Dic | G2: Ene | H2: Feb | I2: Mar | J2: Abr | K2: May | L2: Jun | M2: Jul | N2: Ago | O2: Totales | P2: Sep | Q2: Oct | R2: Nov | S2: Dic | T2: Ene | U2: Feb | V2: Mar | W2: Abr | X2: May | Y2: Jun | Z2: Jul | AA2: Ago | AB2: Totales | AC2: Sep | AD2: Oct | AE2: Nov | AF2: Dic | AG2: Ene | AH2: Feb | AI2: Mar | AJ2: Abr | AK2: May | AL2: Jun | AM2: Jul | AN2: Ago | AO2: Totales | AQ2: Sep | AR2: Oct | AS2: Nov | AT2: Dic | AU2: Ene | AV2: Feb | AW2: Mar | AX2: Abr | AY2: May | AZ2: Jun | BA2: Jul | BB2: Ago | BC2: Totales
B3: Market Intel
B4: Cobros | C4: ='NC-Ingresos'!BY4 -> 32688.786 | D4: ='NC-Ingresos'!BZ4 -> 79900.912 | E4: ='NC-Ingresos'!CA4 -> 42825.233 | F4: ='NC-Ingresos'!CB4 -> 43500 | G4: ='NC-Ingresos'!CC4 -> 79921.479 | H4: ='NC-Ingresos'!CD4 -> 63280.333 | I4: ='NC-Ingresos'!CE4 -> 4535.4389 | J4: ='NC-Ingresos'!CF4 -> 45892.355 | ... N4: ='NC-Ingresos'!CJ4 -> 137858.48 | O4: =SUM(C4:N4) -> 814797.21 | P4: ='NC-Ingresos'!CL4 -> 65669.891 | Q4: ='NC-Ingresos'!CM4 -> 52521.327 | R4: ='NC-Ingresos'!CN4 -> 72545.538 | S4: ='NC-Ingresos'!CO4 -> 44296.859 | T4: ='NC-Ingresos'!CP4 -> 69295.907 | U4: ='NC-Ingresos'!CQ4 -> 188415.03 | V4: ='NC-Ingresos'!CR4 -> 49942.355 | W4: ='NC-Ingresos'!CS4 -> 40241.074 | ... AA4: ='NC-Ingresos'!CW4 -> 30794.444 | AB4: =SUM(P4:AA4) -> 738450.23 | AC4: ='NC-Ingresos'!CY4 -> -15753.245 | AD4: ='NC-Ingresos'!CZ4 -> 36809.702 | AE4: ='NC-Ingresos'!DA4 -> 0 | AF4: ='NC-Ingresos'!DB4 -> 89440.957 | AG4: ='NC-Ingresos'!DC4 -> 36250 | AH4: ='NC-Ingresos'!DD4 -> 55522.949 | AI4: ='NC-Ingresos'!DE4 -> 154869.3 | AJ4: ='NC-Ingresos'!DF4 -> 94488.449 | ... AN4: ='NC-Ingresos'!DJ4 -> 70413.043 | AO4: =SUM(AC4:AN4) -> 1270184 | BC4: =SUM(AQ4:BB4) -> 0
B5: Pagos | C5: ='NC-Gastos'!BY4 -> -23699.643 | D5: ='NC-Gastos'!BZ4 -> -30997.521 | E5: ='NC-Gastos'!CA4 -> -22310.456 | F5: ='NC-Gastos'!CB4 -> -26586.3 | G5: ='NC-Gastos'!CC4 -> -31002.274 | H5: ='NC-Gastos'!CD4 -> -28669.79 | I5: ='NC-Gastos'!CE4 -> -20654.817 | J5: ='NC-Gastos'!CF4 -> -51836.615 | ... N5: ='NC-Gastos'!CJ4 -> -12182.062 | O5: =SUM(C5:N5) -> -332701.61 | P5: ='NC-Gastos'!CL4 -> -22854.57 | Q5: ='NC-Gastos'!CM4 -> -34992.039 | R5: ='NC-Gastos'!CN4 -> -23939.43 | S5: ='NC-Gastos'!CO4 -> -35201.759 | T5: ='NC-Gastos'!CP4 -> -33433.966 | U5: ='NC-Gastos'!CQ4 -> -29391.933 | V5: ='NC-Gastos'!CR4 -> -137630.53 | W5: ='NC-Gastos'!CS4 -> -52016.841 | ... AA5: ='NC-Gastos'!CW4 -> -16586.721 | AB5: =SUM(P5:AA5) -> -490512.8 | AC5: ='NC-Gastos'!CY4 -> -23713.066 | AD5: ='NC-Gastos'!CZ4 -> -60304.337 | AE5: ='NC-Gastos'!DA4 -> -48794.061 | AF5: ='NC-Gastos'!DB4 -> -42438.267 | AG5: ='NC-Gastos'!DC4 -> -45005.811 | AH5: ='NC-Gastos'!DD4 -> -29697.276 | AI5: ='NC-Gastos'!DE4 -> -152955.11 | AJ5: ='NC-Gastos'!DF4 -> -66634.43 | ... AN5: ='NC-Gastos'!DJ4 -> -23288.56 | AO5: =SUM(AC5:AN5) -> -585688.64 | BC5: =SUM(AQ5:BB5) -> 0
B7: Caja Operaciones (mes) | C7: =SUM(C4:C5) -> 8989.1425 | D7: =SUM(D4:D5) -> 48903.391 | E7: =SUM(E4:E5) -> 20514.777 | F7: =SUM(F4:F5) -> 16913.7 | G7: =SUM(G4:G5) -> 48919.205 | H7: =SUM(H4:H5) -> 34610.543 | I7: =SUM(I4:I5) -> -16119.378 | J7: =SUM(J4:J5) -> -5944.2596 | ... N7: =SUM(N4:N5) -> 125676.42 | P7: =SUM(P4:P5) -> 42815.321 | Q7: =SUM(Q4:Q5) -> 17529.289 | R7: =SUM(R4:R5) -> 48606.108 | S7: =SUM(S4:S5) -> 9095.1007 | T7: =SUM(T4:T5) -> 35861.941 | U7: =SUM(U4:U5) -> 159023.09 | V7: =SUM(V4:V5) -> -87688.17 | W7: =SUM(W4:W5) -> -11775.767 | ... AA7: =SUM(AA4:AA5) -> 14207.723 | AC7: =SUM(AC4:AC5) -> -39466.311 | AD7: =SUM(AD4:AD5) -> -23494.635 | AE7: =SUM(AE4:AE5) -> -48794.061 | AF7: =SUM(AF4:AF5) -> 47002.69 | AG7: =SUM(AG4:AG5) -> -8755.8109 | AH7: =SUM(AH4:AH5) -> 25825.673 | AI7: =SUM(AI4:AI5) -> 1914.185 | AJ7: =SUM(AJ4:AJ5) -> 27854.019 | ... AN7: =SUM(AN4:AN5) -> 47124.483
B8: Caja Operaciones (acum.) | C8: =+C7 -> 8989.1425 | D8: =+D7+C8 -> 57892.533 | E8: =+E7+D8 -> 78407.311 | F8: =+F7+E8 -> 95321.011 | G8: =+G7+F8 -> 144240.22 | H8: =+H7+G8 -> 178850.76 | I8: =+I7+H8 -> 162731.38 | J8: =+J7+I8 -> 156787.12 | K8: =+K7+J8 -> 244312.34 | ... N8: =+N7+M8 -> 482095.61 | O8: =SUM(O4:O5) -> 482095.61 | P8: =+P7 -> 42815.321 | Q8: =+Q7+P8 -> 60344.609 | R8: =+R7+Q8 -> 108950.72 | S8: =+S7+R8 -> 118045.82 | T8: =+T7+S8 -> 153907.76 | U8: =+U7+T8 -> 312930.85 | V8: =+V7+U8 -> 225242.68 | W8: =+W7+V8 -> 213466.92 | X8: =+X7+W8 -> 293958.95 | ... AA8: =+AA7+Z8 -> 247937.43 | AB8: =SUM(AB4:AB5) -> 247937.43 | AC8: =+AC7 -> -39466.311 | AD8: =+AD7+AC8 -> -62960.945 | AE8: =+AE7+AD8 -> -111755.01 | AF8: =+AF7+AE8 -> -64752.316 | AG8: =+AG7+AF8 -> -73508.127 | AH8: =+AH7+AG8 -> -47682.453 | AI8: =+AI7+AH8 -> -45768.268 | AJ8: =+AJ7+AI8 -> -17914.249 | AK8: =+AK7+AJ8 -> 214708.49 | ... AN8: =+AN7+AM8 -> 684495.4 | AO8: =SUM(AO4:AO5) -> 684495.4 | BC8: =SUM(BC4:BC5) -> 0
B9: Trade
B10: Cobros | P10: ='Trade-Ingresos'!CL4 -> 0 | Q10: ='Trade-Ingresos'!CM4 -> 0 | R10: ='Trade-Ingresos'!CN4 -> 0 | S10: ='Trade-Ingresos'!CO4 -> 0 | T10: ='Trade-Ingresos'!CP4 -> 526295.29 | U10: ='Trade-Ingresos'!CQ4 -> 522419.65 | V10: ='Trade-Ingresos'!CR4 -> 778499.08 | W10: ='Trade-Ingresos'!CS4 -> 858221.62 | ... AA10: ='Trade-Ingresos'!CW4 -> 1179404.7 | AB10: =SUM(P10:AA10) -> 4937026.5 | AC10: ='Trade-Ingresos'!CY4 -> -1072186.1 | AD10: ='Trade-Ingresos'!CZ4 -> 0 | AE10: ='Trade-Ingresos'!DA4 -> 1579475 | AF10: ='Trade-Ingresos'!DB4 -> 233842.26 | AG10: ='Trade-Ingresos'!DC4 -> 0 | AH10: ='Trade-Ingresos'!DD4 -> 144590.8 | AI10: ='Trade-Ingresos'!DE4 -> 115667.94 | AJ10: ='Trade-Ingresos'!DF4 -> 145805.28 | ... AN10: ='Trade-Ingresos'!DJ4 -> 117500 | AO10: =SUM(AC10:AN10) -> 1639175.7 | BC10: =SUM(AQ10:BB10) -> 0
B11: Pagos | P11: ='Trade-Gastos'!CL4 -> 0 | Q11: ='Trade-Gastos'!CM4 -> 0 | R11: ='Trade-Gastos'!CN4 -> 0 | S11: ='Trade-Gastos'!CO4 -> 0 | T11: ='Trade-Gastos'!CP4 -> -428417.06 | U11: ='Trade-Gastos'!CQ4 -> -543680.83 | V11: ='Trade-Gastos'!CR4 -> -673063.94 | W11: ='Trade-Gastos'!CS4 -> -858753.21 | ... AA11: ='Trade-Gastos'!CW4 -> 0 | AB11: =SUM(P11:AA11) -> -3562884.4 | AC11: ='Trade-Gastos'!CY4 -> -38943.928 | AD11: ='Trade-Gastos'!CZ4 -> -99846.014 | AE11: ='Trade-Gastos'!DA4 -> -528142.27 | AF11: ='Trade-Gastos'!DB4 -> -909159.54 | AG11: ='Trade-Gastos'!DC4 -> -143699.33 | AH11: ='Trade-Gastos'!DD4 -> -28304.34 | AI11: ='Trade-Gastos'!DE4 -> -168310.1 | AJ11: ='Trade-Gastos'!DF4 -> -112846.32 | ... AN11: ='Trade-Gastos'!DJ4 -> -114000 | AO11: =SUM(AC11:AN11) -> -2620199.5 | BC11: =SUM(AQ11:BB11) -> 0
B13: Caja Operaciones (mes) | P13: =SUM(P10:P11) -> 0 | Q13: =SUM(Q10:Q11) -> 0 | R13: =SUM(R10:R11) -> 0 | S13: =SUM(S10:S11) -> 0 | T13: =SUM(T10:T11) -> 97878.23 | U13: =SUM(U10:U11) -> -21261.176 | V13: =SUM(V10:V11) -> 105435.14 | W13: =SUM(W10:W11) -> -531.5858 | ... AA13: =SUM(AA10:AA11) -> 1179404.7 | AC13: =SUM(AC10:AC11) -> -1111130 | AD13: =SUM(AD10:AD11) -> -99846.014 | AE13: =SUM(AE10:AE11) -> 1051332.8 | AF13: =SUM(AF10:AF11) -> -675317.29 | AG13: =SUM(AG10:AG11) -> -143699.33 | AH13: =SUM(AH10:AH11) -> 116286.46 | AI13: =SUM(AI10:AI11) -> -52642.156 | AJ13: =SUM(AJ10:AJ11) -> 32958.96 | ... AN13: =SUM(AN10:AN11) -> 3500
B14: Caja Operaciones (acum.) | P14: =+P13+O14 -> 0 | Q14: =+Q13+P14 -> 0 | R14: =+R13+Q14 -> 0 | S14: =+S13+R14 -> 0 | T14: =+T13+S14 -> 97878.23 | U14: =+U13+T14 -> 76617.054 | V14: =+V13+U14 -> 182052.2 | W14: =+W13+V14 -> 181520.61 | ... AA14: =+AA13+Z14 -> 1374142.1 | AB14: =SUM(AB10:AB11) -> 1374142.1 | AC14: =+AC13 -> -1111130 | AD14: =+AD13+AC14 -> -1210976 | AE14: =+AE13+AD14 -> -159643.27 | AF14: =+AF13+AE14 -> -834960.56 | AG14: =+AG13+AF14 -> -978659.88 | AH14: =+AH13+AG14 -> -862373.42 | AI14: =+AI13+AH14 -> -915015.58 | AJ14: =+AJ13+AI14 -> -882056.62 | AK14: =+AK13+AJ14 -> -938463.95 | ... AN14: =+AN13+AM14 -> -981023.82 | AO14: =SUM(AO10:AO11) -> -981023.82 | AP14: =AO14+1072186+38944+99846 -> 229952.18 | BC14: =SUM(BC10:BC11) -> 0
B15: Actividad Ganadera
B16: Cobros | C16: =Act.Ganadera!BY11 -> 2277.03 | D16: =Act.Ganadera!BZ11 -> 0 | E16: =Act.Ganadera!CA11 -> 0 | F16: =Act.Ganadera!CB11 -> 0 | G16: =Act.Ganadera!CC11 -> 509.17 | H16: =Act.Ganadera!CD11 -> 134.58 | I16: =Act.Ganadera!CE11 -> 0 | J16: =Act.Ganadera!CF11 -> 0 | ... N16: =Act.Ganadera!CJ11 -> 0 | O16: =SUM(C16:N16) -> 2920.78 | P16: =Act.Ganadera!CM11 -> 0 | Q16: =Act.Ganadera!CN11 -> 0 | R16: =Act.Ganadera!CO11 -> 0 | S16: =Act.Ganadera!CP11 -> 18560 | T16: =Act.Ganadera!CQ11 -> 2972.85 | U16: =Act.Ganadera!CR11 -> 0 | V16: =Act.Ganadera!CS11 -> 0 | W16: =Act.Ganadera!CT11 -> 0 | ... AA16: =Act.Ganadera!CX11 -> 0 | AB16: =SUM(P16:AA16) -> 21532.85 | AC16: =Act.Ganadera!CZ11 -> 0 | AD16: =Act.Ganadera!DA11 -> 0 | AE16: =Act.Ganadera!DB11 -> 0 | AF16: =Act.Ganadera!DC11 -> 0 | AG16: =Act.Ganadera!DD11 -> 0 | AH16: =Act.Ganadera!DE11 -> 0 | AI16: =Act.Ganadera!DF11 -> 0 | AJ16: =Act.Ganadera!DG11 -> 0 | ... AN16: =Act.Ganadera!DK11 -> 0 | AO16: =SUM(AC16:AN16) -> 737.53 | BC16: =SUM(AQ16:BB16) -> 0
B17: Pagos | C17: =Act.Ganadera!BY25+Act.Ganadera!BY51 -> -51770.52 | D17: =Act.Ganadera!BZ25+Act.Ganadera!BZ51 -> -1504.79 | E17: =Act.Ganadera!CA25+Act.Ganadera!CA51 -> -21987.725 | F17: =Act.Ganadera!CB25+Act.Ganadera!CB51 -> -13238.728 | G17: =Act.Ganadera!CC25+Act.Ganadera!CC51 -> -29471.34 | H17: =Act.Ganadera!CD25+Act.Ganadera!CD51 -> -32280.45 | I17: =Act.Ganadera!CE25+Act.Ganadera!CE51 -> -14869.92 | J17: =Act.Ganadera!CF25+Act.Ganadera!CF51 -> -5564.36 | ... N17: =Act.Ganadera!CJ25+Act.Ganadera!CJ51 -> 69092.16 | O17: =SUM(C17:N17) -> -170782.21 | P17: =Act.Ganadera!CM25+Act.Ganadera!CM51 -> -14800.2 | Q17: =Act.Ganadera!CN25+Act.Ganadera!CN51 -> -28867.53 | R17: =Act.Ganadera!CO25+Act.Ganadera!CO51 -> -2522.67 | S17: =Act.Ganadera!CP25+Act.Ganadera!CP51 -> -3242.42 | T17: =Act.Ganadera!CQ25+Act.Ganadera!CQ51 -> -14966.05 | U17: =Act.Ganadera!CR25+Act.Ganadera!CR51 -> -20302.74 | V17: =Act.Ganadera!CS25+Act.Ganadera!CS51 -> -20281.49 | W17: =Act.Ganadera!CT25+Act.Ganadera!CT51 -> 2025.34 | ... AA17: =Act.Ganadera!CX25+Act.Ganadera!CX51 -> -10165.692 | AB17: =SUM(P17:AA17) -> -141481.35 | AC17: =Act.Ganadera!CZ25+Act.Ganadera!CZ51 -> -8045.84 | AD17: =Act.Ganadera!DA25+Act.Ganadera!DA51 -> -16162.13 | AE17: =Act.Ganadera!DB25+Act.Ganadera!DB51 -> -2261.05 | AF17: =Act.Ganadera!DC25+Act.Ganadera!DC51 -> -7505.36 | AG17: =Act.Ganadera!DD25+Act.Ganadera!DD51 -> -11435.05 | AH17: =Act.Ganadera!DE25+Act.Ganadera!DE51 -> -6121.96 | AI17: =Act.Ganadera!DF25+Act.Ganadera!DF51 -> -22802.7 | AJ17: =Act.Ganadera!DG25+Act.Ganadera!DG51 -> -253.57 | ... AN17: =Act.Ganadera!DK25+Act.Ganadera!DK51 -> -8247.17 | AO17: =SUM(AC17:AN17) -> -115555.11 | BC17: =SUM(AQ17:BB17) -> 0
B19: Caja Operaciones (mes) | C19: =SUM(C16:C17) -> -49493.49 | D19: =SUM(D16:D17) -> -1504.79 | E19: =SUM(E16:E17) -> -21987.725 | F19: =SUM(F16:F17) -> -13238.728 | G19: =SUM(G16:G17) -> -28962.17 | H19: =SUM(H16:H17) -> -32145.87 | I19: =SUM(I16:I17) -> -14869.92 | J19: =SUM(J16:J17) -> -5564.36 | ... N19: =SUM(N16:N17) -> 69092.16 | P19: =SUM(P16:P17) -> -14800.2 | Q19: =SUM(Q16:Q17) -> -28867.53 | R19: =SUM(R16:R17) -> -2522.67 | S19: =SUM(S16:S17) -> 15317.58 | T19: =SUM(T16:T17) -> -11993.2 | U19: =SUM(U16:U17) -> -20302.74 | V19: =SUM(V16:V17) -> -20281.49 | W19: =SUM(W16:W17) -> 2025.34 | ... AA19: =SUM(AA16:AA17) -> -10165.692 | AC19: =SUM(AC16:AC17) -> -8045.84 | AD19: =SUM(AD16:AD17) -> -16162.13 | AE19: =SUM(AE16:AE17) -> -2261.05 | AF19: =SUM(AF16:AF17) -> -7505.36 | AG19: =SUM(AG16:AG17) -> -11435.05 | AH19: =SUM(AH16:AH17) -> -6121.96 | AI19: =SUM(AI16:AI17) -> -22802.7 | AJ19: =SUM(AJ16:AJ17) -> -253.57 | ... AN19: =SUM(AN16:AN17) -> -8247.17
B20: Caja Operaciones (acum.) | C20: =+C19 -> -49493.49 | D20: =+D19+C20 -> -50998.28 | E20: =+E19+D20 -> -72986.005 | F20: =+F19+E20 -> -86224.733 | G20: =+G19+F20 -> -115186.9 | H20: =+H19+G20 -> -147332.77 | I20: =+I19+H20 -> -162202.69 | J20: =+J19+I20 -> -167767.05 | K20: =+K19+J20 -> -202640.16 | ... N20: =+N19+M20 -> -167861.43 | O20: =SUM(O16:O17) -> -167861.43 | P20: =+P19 -> -14800.2 | Q20: =+Q19+P20 -> -43667.73 | R20: =+R19+Q20 -> -46190.4 | S20: =+S19+R20 -> -30872.82 | T20: =+T19+S20 -> -42866.02 | U20: =+U19+T20 -> -63168.76 | V20: =+V19+U20 -> -83450.25 | W20: =+W19+V20 -> -81424.91 | X20: =+X19+W20 -> -85425.68 | ... AA20: =+AA19+Z20 -> -119948.5 | AB20: =SUM(AB16:AB17) -> -119948.5 | AC20: =+AC19 -> -8045.84 | AD20: =+AD19+AC20 -> -24207.97 | AE20: =+AE19+AD20 -> -26469.02 | AF20: =+AF19+AE20 -> -33974.38 | AG20: =+AG19+AF20 -> -45409.43 | AH20: =+AH19+AG20 -> -51531.39 | AI20: =+AI19+AH20 -> -74334.09 | AJ20: =+AJ19+AI20 -> -74587.66 | AK20: =+AK19+AJ20 -> -75200.63 | ... AN20: =+AN19+AM20 -> -114817.58 | AO20: =SUM(AO16:AO17) -> -114817.58 | BC20: =SUM(BC16:BC17) -> 0
B21: Inversiones
B22: NixAl Commodities | C22: =Inversiones!BY11 -> -1502.78 | D22: =Inversiones!BZ11 -> -1502.78 | E22: =Inversiones!CA11 -> -3353.72 | F22: =Inversiones!CB11 -> -3953.04 | G22: =Inversiones!CC11 -> -6706.405 | H22: =Inversiones!CD11 -> -37062.293 | I22: =Inversiones!CE11 -> -3618.64 | J22: =Inversiones!CF11 -> -3618.64 | ... N22: =Inversiones!CJ11 -> -3695.14 | O22: =SUM(C22:N22) -> -96675.372 | P22: =Inversiones!CM11 -> -3695.14 | Q22: =Inversiones!CN11 -> -3695.14 | R22: =Inversiones!CO11 -> -22859.076 | S22: =Inversiones!CP11 -> -3695.14 | T22: =Inversiones!CQ11 -> -4055.27 | U22: =Inversiones!CR11 -> -4314.99 | V22: =Inversiones!CS11 -> -5276.97 | W22: =Inversiones!CT11 -> -2487.24 | ... AA22: =Inversiones!CX11 -> -1570.97 | AB22: =SUM(P22:AA22) -> -56909.846 | AC22: =Inversiones!CZ11 -> -1570.97 | AD22: =Inversiones!DA11 -> -10739.7 | AE22: =Inversiones!DB11 -> -1570.97 | AF22: =Inversiones!DC11 -> -7581.57 | AG22: =Inversiones!DD11 -> -3901.14 | AH22: =Inversiones!DE11 -> -1570.97 | AI22: =Inversiones!DF11 -> -186491.9 | AJ22: =Inversiones!DG11 -> -4851.7 | ... AN22: =Inversiones!DK11 -> -1570.97 | AO22: =SUM(AC22:AN22) -> -239458 | BC22: =SUM(AQ22:BB22) -> 0
B23: Act. Ganadera | C23: =Inversiones!BY26 -> -410600 | D23: =Inversiones!BZ26 -> 0 | E23: =Inversiones!CA26 -> -5023.58 | F23: =Inversiones!CB26 -> -120341.27 | G23: =Inversiones!CC26 -> -7532.89 | H23: =Inversiones!CD26 -> -15459.55 | I23: =Inversiones!CE26 -> -377.24 | J23: =Inversiones!CF26 -> -1122.45 | ... N23: =Inversiones!CJ26 -> -17049.72 | O23: =SUM(C23:N23) -> -577506.7 | P23: =Inversiones!CM26 -> 0 | Q23: =Inversiones!CN26 -> 0 | R23: =Inversiones!CO26 -> 0 | S23: =Inversiones!CP26 -> 0 | T23: =Inversiones!CQ26 -> 0 | U23: =Inversiones!CR26 -> -1270.1 | V23: =Inversiones!CS26 -> 0 | W23: =Inversiones!CT26 -> -15129.24 | ... AA23: =Inversiones!CX26 -> 0 | AB23: =SUM(P23:AA23) -> -34165.68 | AC23: =Inversiones!CZ26 -> 0 | AD23: =Inversiones!DA26 -> -10587.5 | AE23: =Inversiones!DB26 -> 0 | AF23: =Inversiones!DC26 -> 0 | AG23: =Inversiones!DD26 -> 0 | AH23: =Inversiones!DE26 -> -2013.92 | AI23: =Inversiones!DF26 -> -47795.3 | AJ23: =Inversiones!DG26 -> -1716.87 | ... AN23: =Inversiones!DK26 -> 0 | AO23: =SUM(AC23:AN23) -> -67022.05 | BC23: =SUM(AQ23:BB23) -> 0
B25: Caja Inversiones (mes) | C25: =SUM(C22:C23) -> -412102.78 | D25: =SUM(D22:D23) -> -1502.78 | E25: =SUM(E22:E23) -> -8377.3 | F25: =SUM(F22:F23) -> -124294.31 | G25: =SUM(G22:G23) -> -14239.295 | H25: =SUM(H22:H23) -> -52521.843 | I25: =SUM(I22:I23) -> -3995.88 | J25: =SUM(J22:J23) -> -4741.09 | ... N25: =SUM(N22:N23) -> -20744.86 | P25: =SUM(P22:P23) -> -3695.14 | Q25: =SUM(Q22:Q23) -> -3695.14 | R25: =SUM(R22:R23) -> -22859.076 | S25: =SUM(S22:S23) -> -3695.14 | T25: =SUM(T22:T23) -> -4055.27 | U25: =SUM(U22:U23) -> -5585.09 | V25: =SUM(V22:V23) -> -5276.97 | W25: =SUM(W22:W23) -> -17616.48 | ... AA25: =SUM(AA22:AA23) -> -1570.97 | AC25: =SUM(AC22:AC23) -> -1570.97 | AD25: =SUM(AD22:AD23) -> -21327.2 | AE25: =SUM(AE22:AE23) -> -1570.97 | AF25: =SUM(AF22:AF23) -> -7581.57 | AG25: =SUM(AG22:AG23) -> -3901.14 | AH25: =SUM(AH22:AH23) -> -3584.89 | AI25: =SUM(AI22:AI23) -> -234287.2 | AJ25: =SUM(AJ22:AJ23) -> -6568.57 | ... AN25: =SUM(AN22:AN23) -> -1570.97
B26: Caja Inversiones (acum.) | C26: =+C25 -> -412102.78 | D26: =+D25+C26 -> -413605.56 | E26: =+E25+D26 -> -421982.86 | F26: =+F25+E26 -> -546277.17 | G26: =+G25+F26 -> -560516.47 | H26: =+H25+G26 -> -613038.31 | I26: =+I25+H26 -> -617034.19 | J26: =+J25+I26 -> -621775.28 | K26: =+K25+J26 -> -625393.92 | ... N26: =+N25+M26 -> -674182.07 | O26: =SUM(O22:O23) -> -674182.07 | P26: =+P25 -> -3695.14 | Q26: =+Q25+P26 -> -7390.28 | R26: =+R25+Q26 -> -30249.356 | S26: =+S25+R26 -> -33944.496 | T26: =+T25+S26 -> -37999.766 | U26: =+U25+T26 -> -43584.856 | V26: =+V25+U26 -> -48861.826 | W26: =+W25+V26 -> -66478.306 | X26: =+X25+W26 -> -70129.586 | ... AA26: =+AA25+Z26 -> -91075.526 | AB26: =SUM(AB22:AB23) -> -91075.526 | AC26: =+AC25 -> -1570.97 | AD26: =+AD25+AC26 -> -22898.17 | AE26: =+AE25+AD26 -> -24469.14 | AF26: =+AF25+AE26 -> -32050.71 | AG26: =+AG25+AF26 -> -35951.85 | AH26: =+AH25+AG26 -> -39536.74 | AI26: =+AI25+AH26 -> -273823.94 | AJ26: =+AJ25+AI26 -> -280392.51 | AK26: =+AK25+AJ26 -> -288216.83 | ... AN26: =+AN25+AM26 -> -306480.05 | AO26: =SUM(AO22:AO23) -> -306480.05 | BC26: =SUM(BC22:BC23) -> 0
B27: Financiación | C27: =Financiación!BY4 -> 460898.56 | D27: =Financiación!BZ4 -> 50929.193 | E27: =Financiación!CA4 -> -17795.135 | F27: =Financiación!CB4 -> 222195.88 | G27: =Financiación!CC4 -> -11040.924 | H27: =Financiación!CD4 -> -18191.501 | I27: =Financiación!CE4 -> -164120.39 | J27: =Financiación!CF4 -> -12077.979 | ... N27: =Financiación!CJ4 -> -11624.207 | O27: =SUM(C27:N27) -> 451077.94 | P27: =Financiación!CL4 -> -71050.393 | Q27: =Financiación!CM4 -> -22041.052 | R27: =Financiación!CN4 -> 97064.492 | S27: =Financiación!CO4 -> -39053.978 | T27: =Financiación!CP4 -> -33754.017 | U27: =Financiación!CQ4 -> -21354.518 | V27: =Financiación!CR4 -> -31093.191 | W27: =Financiación!CS4 -> -65717.708 | ... AA27: =Financiación!CW4 -> -156950.81 | AB27: =SUM(P27:AA27) -> -111522.4 | AC27: =Financiación!CY4 -> -74876.79 | AD27: =Financiación!CZ4 -> 107540.31 | AE27: =Financiación!DA4 -> -37738.007 | AF27: =Financiación!DB4 -> -32034.4 | AG27: =Financiación!DC4 -> -49419.317 | AH27: =Financiación!DD4 -> -15576.788 | AI27: =Financiación!DE4 -> 215285.96 | AJ27: =Financiación!DF4 -> -196876.1 | ... AN27: =Financiación!DJ4 -> -26288.998 | AO27: =SUM(AC27:AN27) -> -248274.65 | BC27: =SUM(AQ27:BB27) -> 0
B29: Caja Financiación (mes) | C29: =+C27 -> 460898.56 | D29: =+D27 -> 50929.193 | E29: =+E27 -> -17795.135 | F29: =+F27 -> 222195.88 | G29: =+G27 -> -11040.924 | H29: =+H27 -> -18191.501 | I29: =+I27 -> -164120.39 | J29: =+J27 -> -12077.979 | ... N29: =+N27 -> -11624.207 | P29: =SUM(P27:P27) -> -71050.393 | Q29: =SUM(Q27:Q27) -> -22041.052 | R29: =SUM(R27:R27) -> 97064.492 | S29: =SUM(S27:S27) -> -39053.978 | T29: =SUM(T27:T27) -> -33754.017 | U29: =SUM(U27:U27) -> -21354.518 | V29: =SUM(V27:V27) -> -31093.191 | W29: =SUM(W27:W27) -> -65717.708 | ... AA29: =SUM(AA27:AA27) -> -156950.81 | AC29: =SUM(AC27:AC27) -> -74876.79 | AD29: =SUM(AD27:AD27) -> 107540.31 | AE29: =SUM(AE27:AE27) -> -37738.007 | AF29: =SUM(AF27:AF27) -> -32034.4 | AG29: =SUM(AG27:AG27) -> -49419.317 | AH29: =SUM(AH27:AH27) -> -15576.788 | AI29: =SUM(AI27:AI27) -> 215285.96 | AJ29: =SUM(AJ27:AJ27) -> -196876.1 | ... AN29: =SUM(AN27:AN27) -> -26288.998
B30: Caja Financiación (acum.) | C30: =+C29 -> 460898.56 | D30: =+D29+C30 -> 511827.75 | E30: =+E29+D30 -> 494032.61 | F30: =+F29+E30 -> 716228.5 | G30: =+G29+F30 -> 705187.57 | H30: =+H29+G30 -> 686996.07 | I30: =+I29+H30 -> 522875.68 | J30: =+J29+I30 -> 510797.7 | K30: =+K29+J30 -> 492494.5 | ... N30: =+N29+M30 -> 451077.94 | O30: =SUM(O27:O28) -> 451077.94 | P30: =+P29 -> -71050.393 | Q30: =+Q29+P30 -> -93091.445 | R30: =+R29+Q30 -> 3973.0464 | S30: =+S29+R30 -> -35080.932 | T30: =+T29+S30 -> -68834.949 | U30: =+U29+T30 -> -90189.468 | V30: =+V29+U30 -> -121282.66 | W30: =+W29+V30 -> -187000.37 | X30: =+X29+W30 -> -41755.154 | ... AA30: =+AA29+Z30 -> -111522.4 | AB30: =SUM(AB27:AB28) -> -111522.4 | AC30: =+AC29 -> -74876.79 | AD30: =+AD29+AC30 -> 32663.522 | AE30: =+AE29+AD30 -> -5074.4851 | AF30: =+AF29+AE30 -> -37108.885 | AG30: =+AG29+AF30 -> -86528.202 | AH30: =+AH29+AG30 -> -102104.99 | AI30: =+AI29+AH30 -> 113180.97 | AJ30: =+AJ29+AI30 -> -83695.132 | AK30: =+AK29+AJ30 -> -151352.26 | ... AN30: =+AN29+AM30 -> -248274.65 | AO30: =SUM(AO27:AO28) -> -248274.65 | BC30: =SUM(BC27:BC28) -> 0
B32: Caja opex, capex y serv. deuda | C32: =+C7+C19+C25+C29 -> 8291.4287 | D32: =+D7+D19+D25+D29 -> 96825.014 | E32: =+E7+E19+E25+E29 -> -27645.383 | F32: =+F7+F19+F25+F29 -> 101576.54 | G32: =+G7+G19+G25+G29 -> -5323.1838 | H32: =+H7+H19+H25+H29 -> -68248.671 | I32: =+I7+I19+I25+I29 -> -199105.57 | J32: =+J7+J19+J25+J29 -> -28327.689 | ... N32: =+N7+N19+N25+N29 -> 162399.51 | O32: =SUM(O8,O20,O26,O30) -> 91130.042 | P32: =+P7+P19+P25+P29+P13 -> -46730.412 | Q32: =+Q7+Q19+Q25+Q29+Q13 -> -37074.433 | R32: =+R7+R19+R25+R29+R13 -> 120288.85 | S32: =+S7+S19+S25+S29+S13 -> -18336.438 | T32: =+T7+T19+T25+T29+T13 -> 83937.684 | U32: =+U7+U19+U25+U29+U13 -> 90519.569 | V32: =+V7+V19+V25+V29+V13 -> -38904.68 | W32: =+W7+W19+W25+W29+W13 -> -93616.201 | ... AA32: =+AA7+AA19+AA25+AA29+AA13 -> 1024925 | AB32: =SUM(AB8,AB20,AB26,AB30,AB14) -> 1299533.1 | AC32: =+AC7+AC19+AC25+AC29+AC13 -> -1235089.9 | AD32: =+AD7+AD19+AD25+AD29+AD13 -> -53289.667 | AE32: =+AE7+AE19+AE25+AE29+AE13 -> 960968.69 | AF32: =+AF7+AF19+AF25+AF29+AF13 -> -675435.93 | AG32: =+AG7+AG19+AG25+AG29+AG13 -> -217210.64 | AH32: =+AH7+AH19+AH25+AH29+AH13 -> 116828.5 | AI32: =+AI7+AI19+AI25+AI29+AI13 -> -92531.911 | AJ32: =+AJ7+AJ19+AJ25+AJ29+AJ13 -> -142885.26 | ... AN32: =+AN7+AN19+AN25+AN29+AN13 -> 14517.345 | AO32: =SUM(AO8,AO20,AO26,AO30,AO14) -> -966100.7 | AP32: =AO32-AO14+AP14 -> 244875.3 | BC32: =SUM(BC8,BC20,BC26,BC30,BC14) -> 0
B33: Check | O33: =SUM(C32:N32)-O32 -> 0 | AB33: =SUM(P32:AA32)-AB32 -> 0 | AO33: =SUM(AC32:AN32)-AO32 -> 0 | BC33: =SUM(AQ32:BB32)-BC32 -> 0
B34: Circulante Caixa - 100k Eur | I34: =63000*0 -> 0
B35: Circulante BBVA - 75k Eur | I35: 0
B36: Circulante Bankinter - 100k Eur | I36: =95000*0 -> 0
B37: Total circulante | C37: =SUM(C34:C36) -> 0 | D37: =SUM(D34:D36) -> 0 | E37: =SUM(E34:E36) -> 0 | F37: =SUM(F34:F36) -> 0 | G37: =SUM(G34:G36) -> 0 | H37: =SUM(H34:H36) -> 0 | I37: =SUM(I34:I36) -> 0 | J37: =SUM(J34:J36) -> 0 | ... N37: =SUM(N34:N36) -> 0 | P37: =SUM(P34:P36) -> 0 | Q37: =SUM(Q34:Q36) -> 0 | R37: =SUM(R34:R36) -> 0 | S37: =SUM(S34:S36) -> 0 | T37: =SUM(T34:T36) -> 0 | U37: =SUM(U34:U36) -> 0 | V37: =SUM(V34:V36) -> 0 | W37: =SUM(W34:W36) -> 0 | ... AA37: =SUM(AA34:AA36) -> 0 | AC37: =SUM(AC34:AC36) -> 0 | AD37: =SUM(AD34:AD36) -> 0 | AE37: =SUM(AE34:AE36) -> 0 | AF37: =SUM(AF34:AF36) -> 0 | AG37: =SUM(AG34:AG36) -> 0 | AH37: =SUM(AH34:AH36) -> 0 | AI37: =SUM(AI34:AI36) -> 0 | AJ37: =SUM(AJ34:AJ36) -> 0 | ... AN37: =SUM(AN34:AN36) -> 0
B39: Caja consolidada (mes) | C39: =+C7+C19+C25+C29+C37 -> 8291.4287 | D39: =+D7+D19+D25+D29+D37 -> 96825.014 | E39: =+E7+E19+E25+E29+E37 -> -27645.383 | F39: =+F7+F19+F25+F29+F37 -> 101576.54 | G39: =+G7+G19+G25+G29+G37 -> -5323.1838 | H39: =+H7+H19+H25+H29+H37 -> -68248.671 | I39: =+I7+I19+I25+I29+I37 -> -199105.57 | J39: =+J7+J19+J25+J29+J37 -> -28327.689 | ... N39: =+N7+N19+N25+N29+N37 -> 162399.51 | P39: =+P7+P19+P25+P29+P37 -> -46730.412 | Q39: =+Q7+Q19+Q25+Q29+Q37 -> -37074.433 | R39: =+R7+R19+R25+R29+R37 -> 120288.85 | S39: =+S7+S19+S25+S29+S37 -> -18336.438 | T39: =+T7+T19+T13+T25+T29+T37 -> 83937.684 | U39: =+U7+U19+U13+U25+U29+U37 -> 90519.569 | V39: =+V7+V19+V13+V25+V29+V37 -> -38904.68 | W39: =+W7+W19+W13+W25+W29+W37 -> -93616.201 | X39: =+X7+X19+X13+X25+X29+X37 -> 157576 | Y39: =+Y7+Y19+Y13+Y25+Y29+Y37 -> -96301.983 | Z39: =+Z7+Z19+Z13+Z25+Z29+Z37 -> 153250.16 | AA39: =+AA7+AA19+AA13+AA25+AA29+AA37 -> 1024925 | AC39: =+AC7+AC19+AC13+AC25+AC29+AC37 -> -1235089.9 | AD39: =+AD7+AD19+AD13+AD25+AD29+AD37 -> -53289.667 | AE39: =+AE7+AE19+AE13+AE25+AE29+AE37 -> 960968.69 | AF39: =+AF7+AF19+AF13+AF25+AF29+AF37 -> -675435.93 | AG39: =+AG7+AG19+AG13+AG25+AG29+AG37 -> -217210.64 | AH39: =+AH7+AH19+AH13+AH25+AH29+AH37 -> 116828.5 | AI39: =+AI7+AI19+AI13+AI25+AI29+AI37 -> -92531.911 | AJ39: =+AJ7+AJ19+AJ13+AJ25+AJ29+AJ37 -> -142885.26 | ... AN39: =+AN7+AN19+AN13+AN25+AN29+AN37 -> 14517.345
B40: Caja consolidada (acumulada) | C40: =+C39 -> 8291.4287 | D40: =+D39+C40 -> 105116.44 | E40: =+E39+D40 -> 77471.06 | F40: =+F39+E40 -> 179047.6 | G40: =+G39+F40 -> 173724.42 | H40: =+H39+G40 -> 105475.75 | I40: =+I39+H40 -> -93629.819 | J40: =+J39+I40 -> -121957.51 | K40: =+K39+J40 -> -91227.237 | ... N40: =+N39+M40 -> 91130.042 | P40: =+P39 -> -46730.412 | Q40: =+Q39+P40 -> -83804.846 | R40: =+R39+Q40 -> 36484.008 | S40: =+S39+R40 -> 18147.571 | T40: =+T39+S40 -> 102085.25 | U40: =+U39+T40 -> 192604.82 | V40: =+V39+U40 -> 153700.14 | W40: =+W39+V40 -> 60083.943 | X40: =+X39+W40 -> 217659.95 | ... AA40: =+AA39+Z40 -> 1299533.1 | AC40: =+AC39 -> -1235089.9 | AD40: =+AD39+AC40 -> -1288379.6 | AE40: =+AE39+AD40 -> -327410.92 | AF40: =+AF39+AE40 -> -1002846.9 | AG40: =+AG39+AF40 -> -1220057.5 | AH40: =+AH39+AG40 -> -1103229 | AI40: =+AI39+AH40 -> -1195760.9 | AJ40: =+AJ39+AI40 -> -1338646.2 | AK40: =+AK39+AJ40 -> -1238525.2 | ... AN40: =+AN39+AM40 -> -966100.7
B42: Saldo Inicial | C42: =Tesoreria!$BW$315 -> 65108.2 | H42: =Tesoreria!$CC$302 -> 240150.56 | I42: =+H44 -> 171901.89 | J42: =+I44 -> -27203.678 | K42: =+J44 -> -55531.367 | L42: =+K44 -> -24801.096 | M42: =+L44 -> 7269.8771 | N42: =+M44 -> -4843.327 | P42: =+N44 -> 157556.18 | Q42: =+P44 -> 110825.77 | R42: =+Q44 -> 73751.338 | S42: =+R44 -> 194040.19 | T42: =+S44 -> 175703.75 | U42: =+T44 -> 259641.44 | V42: =+U44 -> 350161.01 | W42: =+V44 -> 311256.33 | X42: =+W44 -> 217640.13 | ... AA42: =+Z44 -> 432164.31 | AC42: =+AA44 -> 1457089.3 | AD42: =+AC44 -> 221999.33 | AE42: =+AD44 -> 168709.67 | AF42: =+AE44 -> 1129678.4 | AG42: =+AF44 -> 454242.43 | AH42: =+AG44 -> 237031.78 | AI42: =+AH44 -> 353860.28 | AJ42: =+AI44 -> 261328.37 | AK42: =+AJ44 -> 118443.11 | ... AN42: =+AM44 -> 476471.23
B43: Caja consolidada | C43: =+C39 -> 8291.4287 | H43: =+H39 -> -68248.671 | I43: =+I39 -> -199105.57 | J43: =+J39 -> -28327.689 | K43: =+K39 -> 30730.271 | L43: =+L39 -> 32070.973 | M43: =+M39 -> -12113.204 | N43: =+N39 -> 162399.51 | P43: =+P39 -> -46730.412 | Q43: =+Q39 -> -37074.433 | R43: =+R39 -> 120288.85 | S43: =+S39 -> -18336.438 | T43: =+T39 -> 83937.684 | U43: =+U39 -> 90519.569 | V43: =+V39 -> -38904.68 | W43: =+W39 -> -93616.201 | ... AA43: =+AA39 -> 1024925 | AC43: =+AC39 -> -1235089.9 | AD43: =+AD39 -> -53289.667 | AE43: =+AE39 -> 960968.69 | AF43: =+AF39 -> -675435.93 | AG43: =+AG39 -> -217210.64 | AH43: =+AH39 -> 116828.5 | AI43: =+AI39 -> -92531.911 | AJ43: =+AJ39 -> -142885.26 | ... AN43: =+AN39 -> 14517.345
B44: Saldo final | C44: =SUM(C42:C43) -> 73399.629 | H44: =SUM(H42:H43) -> 171901.89 | I44: =SUM(I42:I43) -> -27203.678 | J44: =SUM(J42:J43) -> -55531.367 | K44: =SUM(K42:K43) -> -24801.096 | L44: =SUM(L42:L43) -> 7269.8771 | M44: =SUM(M42:M43) -> -4843.327 | N44: =SUM(N42:N43) -> 157556.18 | P44: =SUM(P42:P43) -> 110825.77 | Q44: =SUM(Q42:Q43) -> 73751.338 | R44: =SUM(R42:R43) -> 194040.19 | S44: =SUM(S42:S43) -> 175703.75 | T44: =SUM(T42:T43) -> 259641.44 | U44: =SUM(U42:U43) -> 350161.01 | V44: =SUM(V42:V43) -> 311256.33 | W44: =SUM(W42:W43) -> 217640.13 | ... AA44: =SUM(AA42:AA43) -> 1457089.3 | AC44: =SUM(AC42:AC43) -> 221999.33 | AD44: =SUM(AD42:AD43) -> 168709.67 | AE44: =SUM(AE42:AE43) -> 1129678.4 | AF44: =SUM(AF42:AF43) -> 454242.43 | AG44: =SUM(AG42:AG43) -> 237031.78 | AH44: =SUM(AH42:AH43) -> 353860.28 | AI44: =SUM(AI42:AI43) -> 261328.37 | AJ44: =SUM(AJ42:AJ43) -> 118443.11 | ... AN44: =SUM(AN42:AN43) -> 490988.58
B45: Saldos bancarios
B46: Saldo BBVA EUR | H46: =10469.53-74136.86 -> -63667.33 | I46: =2523.06-73109.06 -> -70586 | J46: =2514.76-74109.06 -> -71594.3 | K46: =1734.67-74109.06 -> -72374.39 | L46: =577.32-74213.91 -> -73636.59 | M46: =172.75-74213.91 -> -74041.16 | N46: =362.27-74213.91 -> -73851.64 | P46: =351.65-72713.91 -> -72362.26 | Q46: =341.03-74271.06 -> -73930.03 | R46: =330.41-74271.06 -> -73940.65 | S46: =319.79-72771.06 -> -72451.27 | T46: =294.62-74186.7 -> -73892.08 | U46: =2195.46-74386.7 -> -72191.24 | V46: =483.08-73622.53 -> -73139.45 | W46: =537.91-61827.58 -> -61289.67 | X46: =3860.91-61827.58 -> -57966.67 | Y46: =647.57-61827.58 -> -61180.01 | Z46: =725.42-62698.58 -> -61973.16 | AA46: =3731.68-45149.18 -> -41417.5 | AC46: =564.38-72149.18 -> -71584.8 | AD46: =642.23-52826.48 -> -52184.25 | AE46: =3965.23+551998.36 -> 555963.59 | AF46: =797.93+28698.81 -> 29496.74 | AG46: =4040.93+28437 -> 32477.93 | AH46: =3870.48+11290.75 -> 15161.23 | AI46: =1267.32-12656.03 -> -11388.71 | AJ46: =1343.4-62388.9 -> -61045.5 | AK46: =4664.4-63003.14 -> -58338.74
B47: Saldo Caixa EUR | H47: 40260.41 | I47: -28069.15 | J47: -50198.29 | K47: -65493.99 | L47: -83056.87 | M47: -78659.97 | N47: -50350.62 | P47: -77272.07 | Q47: -54046.85 | R47: 38618.95 | S47: -3841.8 | T47: 7909.13 | U47: -14135.47 | V47: -50758.09 | W47: -59040.57 | X47: -15300.11 | Y47: -37916.4 | Z47: 109670.4 | AA47: 1253592.1 | AC47: =55527.26+27000+22000 -> 104527.26 | AD47: 28541.07 | AE47: 273961.03 | AF47: 101854.88 | AG47: -50866.66 | AH47: =-48475.75 -> -48475.75 | AI47: =-22286.57 -> -22286.57 | AJ47: -61776.02 | AK47: -54597.91 | AL47: =AK47+AL32 -> 54244.601 | AM47: =AL47+AM32 -> 203309.23 | AN47: =AM47+AN32 -> 217826.57
B48: Saldo Caixa USD (valor aprox €) | H48: 0 | I48: 0 | J48: 0 | K48: 0 | L48: 0 | M48: 0 | N48: 0 | P48: 0 | Q48: 0 | R48: 0 | S48: 0 | T48: 0 | U48: 0 | V48: 0 | W48: 0 | X48: 0 | Y48: 0 | Z48: 0 | AA48: 0 | AC48: 0 | AD48: 0 | AE48: 0 | AF48: 0 | AG48: 0 | AH48: 0 | AI48: 0 | AJ48: 0 | AK48: 0
...

Sheet NC-Ingresos
C2: 2018 | P2: 2019 | AC2: 2020 | AL2: 2020/2021 | AY2: 2021/2022 | BL2: 2022/2023 | BY2: 2023/2024 | CL2: 2024/2025 | CY2: 2025/2026 | DL2: 2026/2027
B3: Previsiones Caja | C3: Ene | D3: Feb | E3: Mar | F3: Abr | G3: May | H3: Jun | I3: Jul | J3: Ago | K3: Sep | L3: Oct | M3: Nov | N3: Dic | O3: Totales | P3: Ene | Q3: Feb | R3: Mar | S3: Abr | T3: May | U3: Jun | V3: Jul | W3: Ago | X3: Sep | Y3: Oct | Z3: Nov | AA3: Dic | AB3: Totales | AC3: Ene | AD3: Feb | AE3: Mar | AF3: Abr | AG3: May | AH3: Jun | AI3: Jul | AJ3: Ago | AK3: Totales | AL3: Sep | AM3: Oct | AN3: Nov | AO3: Dic | AP3: Ene | AQ3: Feb | AR3: Mar | AS3: Abr | AT3: May | AU3: Jun | AV3: Jul | AW3: Ago | AX3: Totales | AY3: Sep | AZ3: Oct | BA3: Nov | BB3: Dic | BC3: Ene | BD3: Feb | BE3: Mar | BF3: Abr | BG3: May | BH3: Jun | BI3: Jul | BJ3: Ago | BK3: Totales | BL3: Sep | BM3: Oct | BN3: Nov | BO3: Dic | BP3: Ene | BQ3: Feb | BR3: Mar | BS3: Abr | BT3: May | BU3: Jun | BV3: Jul | BW3: Ago | BX3: Totales | BY3: Sep | BZ3: Oct | CA3: Nov | CB3: Dic | CC3: Ene | CD3: Feb | CE3: Mar | CF3: Abr | CG3: May | CH3: Jun | CI3: Jul | CJ3: Ago | CK3: Totales | CL3: Sep | CM3: Oct | CN3: Nov | CO3: Dic | CP3: Ene | CQ3: Feb | CR3: Mar | CS3: Abr | CT3: May | CU3: Jun | CV3: Jul | CW3: Ago | CX3: Totales | CY3: Sep | CZ3: Oct | DA3: Nov | DB3: Dic | DC3: Ene | DD3: Feb | DE3: Mar | DF3: Abr | DG3: May | DH3: Jun | DI3: Jul | DJ3: Ago | DK3: Totales | DL3: Sep | DM3: Oct | DN3: Nov | DO3: Dic | DP3: Ene | DQ3: Feb | DR3: Mar | DS3: Abr | DT3: May | DU3: Jun | DV3: Jul | DW3: Ago | DX3: Totales
